Workbook

Sheet Arbitrage
A1: Date | B1: Sportsbook1(F) | C1: Sportsbook2(U) | D1: Prop(F/U) | E1: Line1(F) | F1: Line2(U) | G1: FreeRollPick(F/U) | H1: EvenProfitMargin | I1: FreeRollProfitMargin | J1: TotalAmountWagering | K1: EvenAmount1(F) | L1: EvenAmount2(U) | M1: EvenProfit | N1: FreeRollAmount1(F) | O1: FreeRollAmount2(U) | P1: FreeRollProfit | Q1: E/F? (EvenProfit/FreeRoll) | R1: Event(F/U)? | S1: PROFIT REALIZED | U1: TOTAL PROFIT | X1: DATE | Y1: PROFIT | AA1: ACCOUNTS | AB1: START | AC1: END
A2: 45236 | B2: Fanduel | C2: Betano | D2: Justin Herbert Rushing Attempts (U/O 3.5) | E2: -114 | F2: 125 | G2: F | H2: =IF(E2<0,100*(E2+F2)/(10000-200*E2-E2*F2),IF(E2>0,(E2*F2-10000)/(100*(E2+F2+200)),0)) -> 0.023379384 | I2: =IF(E2<0,IF(G2="F",-100*(E2+F2)/(E2*(F2+100)),IF(G2="U",-(F2+E2)/(E2-100),0)),IF(E2>0,IF(G2="F",(E2*F2-10000)/(100*F2+10000),IF(G2="U",(E2*F2-10000)/(100*E2+10000),0)),0)) -> 0.04288499 | J2: 1125 | K2: =IF(E2<0,(H2*J2*-E2*(1+F2/100))/(E2+F2),(100*H2*J2*(100+F2))/(E2*F2-10000)) -> 613.31031 | L2: =IF(E2<0,((100-E2)*H2*J2)/(E2+F2),100*((100+E2)*H2*J2)/(E2*F2-10000)) -> 511.68969 | M2: =H2*J2 -> 26.301807 | N2: =IF(G2="F",(F2*J2)/(100+F2),IF(G2="U",IF(E2<0,(-E2*J2)/(100-E2),IF(E2>0,(100*J2)/(E2+100),0)),0)) -> 625 | O2: =IF(AND(G2="F",E2<>""),(100*J2)/(100+F2),IF(G2="U",IF(E2<0,(100*J2)/(100-E2),IF(E2>0,(E2*J2)/(E2+100),0)),0)) -> 500 | P2: =I2*J2 -> 48.245614 | Q2: F | R2: F | S2: =IF((Q2="F"),IF(R2=G2,P2,0),IF(Q2="E",M2,0)) -> 48.245614 | U2: =SUM(S:S) -> 2130.9386 | W2: WEEK 1 | X2: 45236 | Y2: {=SUM(_xlfn._xlws.FILTER(S:S,A:A=X2,0))} -> 48.245614 | AA2: SCOTIA | AB2: 15800 | AC2: 4289.91
A3: 45236 | B3: Fanduel | C3: Betano | D3: Vancouver Cancucks/Edmonton Oilers | E3: 100 | F3: 102 | G3: U | H3: =IF(E3<0,100*(E3+F3)/(10000-200*E3-E3*F3),IF(E3>0,(E3*F3-10000)/(100*(E3+F3+200)),0)) -> 0.0049751244 | I3: =IF(E3<0,IF(G3="F",-100*(E3+F3)/(E3*(F3+100)),IF(G3="U",-(F3+E3)/(E3-100),0)),IF(E3>0,IF(G3="F",(E3*F3-10000)/(100*F3+10000),IF(G3="U",(E3*F3-10000)/(100*E3+10000),0)),0)) -> 0.01 | J3: 2000 | K3: =IF(E3<0,(H3*J3*-E3*(1+F3/100))/(E3+F3),(100*H3*J3*(100+F3))/(E3*F3-10000)) -> 1004.9751 | L3: =IF(E3<0,((100-E3)*H3*J3)/(E3+F3),100*((100+E3)*H3*J3)/(E3*F3-10000)) -> 995.02488 | M3: =H3*J3 -> 9.9502488 | N3: =IF(G3="F",(F3*J3)/(100+F3),IF(G3="U",IF(E3<0,(-E3*J3)/(100-E3),IF(E3>0,(100*J3)/(E3+100),0)),0)) -> 1000 | O3: =IF(AND(G3="F",E3<>""),(100*J3)/(100+F3),IF(G3="U",IF(E3<0,(100*J3)/(100-E3),IF(E3>0,(E3*J3)/(E3+100),0)),0)) -> 1000 | P3: =I3*J3 -> 20 | Q3: F | R3: F | S3: =IF((Q3="F"),IF(R3=G3,P3,0),IF(Q3="E",M3,0)) -> 0 | U3: WAGERED | W3: =SUM(Y2:Y7) -> 141.99561 | X3: 45237 | Y3: {=SUM(_xlfn._xlws.FILTER(S:S,A:A=X3,0))} -> 0 | AA3: Bet365 | AB3: 0 | AC3: 4394.46
A4: 45238 | B4: DraftKings | C4: Bet365 | D4: Lauri Markkanen Threes Made (U/O 3.5) | E4: 100 | F4: 110 | G4: U | H4: =IF(E4<0,100*(E4+F4)/(10000-200*E4-E4*F4),IF(E4>0,(E4*F4-10000)/(100*(E4+F4+200)),0)) -> 0.024390244 | I4: =IF(E4<0,IF(G4="F",-100*(E4+F4)/(E4*(F4+100)),IF(G4="U",-(F4+E4)/(E4-100),0)),IF(E4>0,IF(G4="F",(E4*F4-10000)/(100*F4+10000),IF(G4="U",(E4*F4-10000)/(100*E4+10000),0)),0)) -> 0.05 | J4: 1000 | K4: =IF(E4<0,(H4*J4*-E4*(1+F4/100))/(E4+F4),(100*H4*J4*(100+F4))/(E4*F4-10000)) -> 512.19512 | L4: =IF(E4<0,((100-E4)*H4*J4)/(E4+F4),100*((100+E4)*H4*J4)/(E4*F4-10000)) -> 487.80488 | M4: =H4*J4 -> 24.390244 | N4: =IF(G4="F",(F4*J4)/(100+F4),IF(G4="U",IF(E4<0,(-E4*J4)/(100-E4),IF(E4>0,(100*J4)/(E4+100),0)),0)) -> 500 | O4: =IF(AND(G4="F",E4<>""),(100*J4)/(100+F4),IF(G4="U",IF(E4<0,(100*J4)/(100-E4),IF(E4>0,(E4*J4)/(E4+100),0)),0)) -> 500 | P4: =I4*J4 -> 50 | Q4: F | R4: F | S4: =IF((Q4="F"),IF(R4=G4,P4,0),IF(Q4="E",M4,0)) -> 0 | U4: =SUM(J:J) -> 108801.3 | X4: 45238 | Y4: {=SUM(_xlfn._xlws.FILTER(S:S,A:A=X4,0))} -> 93.75 | AA4: Betano | AB4: 0 | AC4: 1391.95
A5: 45238 | B5: Bet365 | C5: DraftKings | D5: Brandon Ingram Assists (U/O 6.5) | E5: 100 | F5: 110 | G5: U | H5: =IF(E5<0,100*(E5+F5)/(10000-200*E5-E5*F5),IF(E5>0,(E5*F5-10000)/(100*(E5+F5+200)),0)) -> 0.024390244 | I5: =IF(E5<0,IF(G5="F",-100*(E5+F5)/(E5*(F5+100)),IF(G5="U",-(F5+E5)/(E5-100),0)),IF(E5>0,IF(G5="F",(E5*F5-10000)/(100*F5+10000),IF(G5="U",(E5*F5-10000)/(100*E5+10000),0)),0)) -> 0.05 | J5: 1000 | K5: =IF(E5<0,(H5*J5*-E5*(1+F5/100))/(E5+F5),(100*H5*J5*(100+F5))/(E5*F5-10000)) -> 512.19512 | L5: =IF(E5<0,((100-E5)*H5*J5)/(E5+F5),100*((100+E5)*H5*J5)/(E5*F5-10000)) -> 487.80488 | M5: =H5*J5 -> 24.390244 | N5: =IF(G5="F",(F5*J5)/(100+F5),IF(G5="U",IF(E5<0,(-E5*J5)/(100-E5),IF(E5>0,(100*J5)/(E5+100),0)),0)) -> 500 | O5: =IF(AND(G5="F",E5<>""),(100*J5)/(100+F5),IF(G5="U",IF(E5<0,(100*J5)/(100-E5),IF(E5>0,(E5*J5)/(E5+100),0)),0)) -> 500 | P5: =I5*J5 -> 50 | Q5: F | R5: F | S5: =IF((Q5="F"),IF(R5=G5,P5,0),IF(Q5="E",M5,0)) -> 0 | U5: PROFIT MARGIN | X5: 45239 | Y5: {=SUM(_xlfn._xlws.FILTER(S:S,A:A=X5,0))} -> 0 | AA5: Fanduel | AB5: 0 | AC5: 3004.1
A6: 45238 | B6: DraftKings | C6: Bet365 | D6: Chris Paul Threes Made (O/U 0.5) | E6: -160 | F6: 185 | G6: F | H6: =IF(E6<0,100*(E6+F6)/(10000-200*E6-E6*F6),IF(E6>0,(E6*F6-10000)/(100*(E6+F6+200)),0)) -> 0.034916201 | I6: =IF(E6<0,IF(G6="F",-100*(E6+F6)/(E6*(F6+100)),IF(G6="U",-(F6+E6)/(E6-100),0)),IF(E6>0,IF(G6="F",(E6*F6-10000)/(100*F6+10000),IF(G6="U",(E6*F6-10000)/(100*E6+10000),0)),0)) -> 0.054824561 | J6: 1710 | K6: =IF(E6<0,(H6*J6*-E6*(1+F6/100))/(E6+F6),(100*H6*J6*(100+F6))/(E6*F6-10000)) -> 1089.0503 | L6: =IF(E6<0,((100-E6)*H6*J6)/(E6+F6),100*((100+E6)*H6*J6)/(E6*F6-10000)) -> 620.94972 | M6: =H6*J6 -> 59.706704 | N6: =IF(G6="F",(F6*J6)/(100+F6),IF(G6="U",IF(E6<0,(-E6*J6)/(100-E6),IF(E6>0,(100*J6)/(E6+100),0)),0)) -> 1110 | O6: =IF(AND(G6="F",E6<>""),(100*J6)/(100+F6),IF(G6="U",IF(E6<0,(100*J6)/(100-E6),IF(E6>0,(E6*J6)/(E6+100),0)),0)) -> 600 | P6: =I6*J6 -> 93.75 | Q6: F | R6: F | S6: =IF((Q6="F"),IF(R6=G6,P6,0),IF(Q6="E",M6,0)) -> 93.75 | U6: =U2/U4 -> 0.019585598 | X6: 45240 | Y6: {=SUM(_xlfn._xlws.FILTER(S:S,A:A=X6,0))} -> 0 | AA6: PokerStars | AB6: 0 | AC6: 680.6
A7: 45254 | B7: UniBet | C7: BetVictor/Fanduel | D7: Dimitri Van den Bergh v Jim Williams | E7: -127 | F7: 138 | G7: F | H7: =IF(E7<0,100*(E7+F7)/(10000-200*E7-E7*F7),IF(E7>0,(E7*F7-10000)/(100*(E7+F7+200)),0)) -> 0.020783736 | I7: =IF(E7<0,IF(G7="F",-100*(E7+F7)/(E7*(F7+100)),IF(G7="U",-(F7+E7)/(E7-100),0)),IF(E7>0,IF(G7="F",(E7*F7-10000)/(100*F7+10000),IF(G7="U",(E7*F7-10000)/(100*E7+10000),0)),0)) -> 0.03639251 | J7: 1602.27 | K7: =IF(E7<0,(H7*J7*-E7*(1+F7/100))/(E7+F7),(100*H7*J7*(100+F7))/(E7*F7-10000)) -> 915.05523 | L7: =IF(E7<0,((100-E7)*H7*J7)/(E7+F7),100*((100+E7)*H7*J7)/(E7*F7-10000)) -> 687.21477 | M7: =H7*J7 -> 33.301156 | N7: =IF(G7="F",(F7*J7)/(100+F7),IF(G7="U",IF(E7<0,(-E7*J7)/(100-E7),IF(E7>0,(100*J7)/(E7+100),0)),0)) -> 929.04731 | O7: =IF(AND(G7="F",E7<>""),(100*J7)/(100+F7),IF(G7="U",IF(E7<0,(100*J7)/(100-E7),IF(E7>0,(E7*J7)/(E7+100),0)),0)) -> 673.22269 | P7: =I7*J7 -> 58.310627 | Q7: F | R7: F | S7: =IF((Q7="F"),IF(R7=G7,P7,0),IF(Q7="E",M7,0)) -> 58.310627 | U7: AVERAGE WEEKLY INCOME | X7: 45241 | Y7: {=SUM(_xlfn._xlws.FILTER(S:S,A:A=X7,0))} -> 0 | AA7: TheScore | AB7: 0 | AC7: 3426.4
A8: 45251 | B8: Betano | C8: Fanduel | D8: Uruguay vs Bolivia Both Teams to Score (N/Y) | E8: -238 | F8: 270 | G8: U | H8: =IF(E8<0,100*(E8+F8)/(10000-200*E8-E8*F8),IF(E8>0,(E8*F8-10000)/(100*(E8+F8+200)),0)) -> 0.026259642 | I8: =IF(E8<0,IF(G8="F",-100*(E8+F8)/(E8*(F8+100)),IF(G8="U",-(F8+E8)/(E8-100),0)),IF(E8>0,IF(G8="F",(E8*F8-10000)/(100*F8+10000),IF(G8="U",(E8*F8-10000)/(100*E8+10000),0)),0)) -> 0.094674556 | J8: 1000 | K8: =IF(E8<0,(H8*J8*-E8*(1+F8/100))/(E8+F8),(100*H8*J8*(100+F8))/(E8*F8-10000)) -> 722.63253 | L8: =IF(E8<0,((100-E8)*H8*J8)/(E8+F8),100*((100+E8)*H8*J8)/(E8*F8-10000)) -> 277.36747 | M8: =H8*J8 -> 26.259642 | N8: =IF(G8="F",(F8*J8)/(100+F8),IF(G8="U",IF(E8<0,(-E8*J8)/(100-E8),IF(E8>0,(100*J8)/(E8+100),0)),0)) -> 704.14201 | O8: =IF(AND(G8="F",E8<>""),(100*J8)/(100+F8),IF(G8="U",IF(E8<0,(100*J8)/(100-E8),IF(E8>0,(E8*J8)/(E8+100),0)),0)) -> 295.85799 | P8: =I8*J8 -> 94.674556 | Q8: F | R8: F | S8: =IF((Q8="F"),IF(R8=G8,P8,0),IF(Q8="E",M8,0)) -> 0 | U8: =AVERAGE(W3,W9,W16,W23,W30,W37,W44,W51) -> 266.36732 | W8: WEEK 2 | X8: 45242 | Y8: {=SUM(_xlfn._xlws.FILTER(S:S,A:A=X8,0))} -> 0 | AA8: Unibet | AB8: 0 | AC8: 0
A9: 45244 | B9: DraftKings | C9: Betano | D9: Ryan Kalkbrenner Rebounds (U/O 5.5) | E9: -110 | F9: 115 | G9: F | H9: =IF(E9<0,100*(E9+F9)/(10000-200*E9-E9*F9),IF(E9>0,(E9*F9-10000)/(100*(E9+F9+200)),0)) -> 0.011198208 | I9: =IF(E9<0,IF(G9="F",-100*(E9+F9)/(E9*(F9+100)),IF(G9="U",-(F9+E9)/(E9-100),0)),IF(E9>0,IF(G9="F",(E9*F9-10000)/(100*F9+10000),IF(G9="U",(E9*F9-10000)/(100*E9+10000),0)),0)) -> 0.021141649 | J9: 322.5 | K9: =IF(E9<0,(H9*J9*-E9*(1+F9/100))/(E9+F9),(100*H9*J9*(100+F9))/(E9*F9-10000)) -> 170.82027 | L9: =IF(E9<0,((100-E9)*H9*J9)/(E9+F9),100*((100+E9)*H9*J9)/(E9*F9-10000)) -> 151.67973 | M9: =H9*J9 -> 3.6114222 | N9: =IF(G9="F",(F9*J9)/(100+F9),IF(G9="U",IF(E9<0,(-E9*J9)/(100-E9),IF(E9>0,(100*J9)/(E9+100),0)),0)) -> 172.5 | O9: =IF(AND(G9="F",E9<>""),(100*J9)/(100+F9),IF(G9="U",IF(E9<0,(100*J9)/(100-E9),IF(E9>0,(E9*J9)/(E9+100),0)),0)) -> 150 | P9: =I9*J9 -> 6.8181818 | Q9: F | R9: F | S9: =IF((Q9="F"),IF(R9=G9,P9,0),IF(Q9="E",M9,0)) -> 6.8181818 | W9: =SUM(Y8:Y14) -> 137.9682 | X9: 45243 | Y9: {=SUM(_xlfn._xlws.FILTER(S:S,A:A=X9,0))} -> 0 | AA9: Northstar | AB9: 0 | AC9: 1101.18
A10: 45244 | B10: Fanduel | C10: Betano | D10: LeBron James Threes Made (O/U 1.5) | E10: -130 | F10: 140 | G10: F | H10: =IF(E10<0,100*(E10+F10)/(10000-200*E10-E10*F10),IF(E10>0,(E10*F10-10000)/(100*(E10+F10+200)),0)) -> 0.018450185 | I10: =IF(E10<0,IF(G10="F",-100*(E10+F10)/(E10*(F10+100)),IF(G10="U",-(F10+E10)/(E10-100),0)),IF(E10>0,IF(G10="F",(E10*F10-10000)/(100*F10+10000),IF(G10="U",(E10*F10-10000)/(100*E10+10000),0)),0)) -> 0.032051282 | J10: 447.43 | K10: =IF(E10<0,(H10*J10*-E10*(1+F10/100))/(E10+F10),(100*H10*J10*(100+F10))/(E10*F10-10000)) -> 257.56118 | L10: =IF(E10<0,((100-E10)*H10*J10)/(E10+F10),100*((100+E10)*H10*J10)/(E10*F10-10000)) -> 189.86882 | M10: =H10*J10 -> 8.2551661 | N10: =IF(G10="F",(F10*J10)/(100+F10),IF(G10="U",IF(E10<0,(-E10*J10)/(100-E10),IF(E10>0,(100*J10)/(E10+100),0)),0)) -> 261.00083 | O10: =IF(AND(G10="F",E10<>""),(100*J10)/(100+F10),IF(G10="U",IF(E10<0,(100*J10)/(100-E10),IF(E10>0,(E10*J10)/(E10+100),0)),0)) -> 186.42917 | P10: =I10*J10 -> 14.340705 | Q10: F | R10: F | S10: =IF((Q10="F"),IF(R10=G10,P10,0),IF(Q10="E",M10,0)) -> 14.340705 | X10: 45244 | Y10: {=SUM(_xlfn._xlws.FILTER(S:S,A:A=X10,0))} -> 137.9682 | AA10: Proline+ | AB10: 0 | AC10: 0
A11: 45244 | B11: Fanduel | C11: Bet365 | D11: LeBron James Threes Made (O/U 1.5) | E11: -130 | F11: 150 | G11: F | H11: =IF(E11<0,100*(E11+F11)/(10000-200*E11-E11*F11),IF(E11>0,(E11*F11-10000)/(100*(E11+F11+200)),0)) -> 0.036036036 | I11: =IF(E11<0,IF(G11="F",-100*(E11+F11)/(E11*(F11+100)),IF(G11="U",-(F11+E11)/(E11-100),0)),IF(E11>0,IF(G11="F",(E11*F11-10000)/(100*F11+10000),IF(G11="U",(E11*F11-10000)/(100*E11+10000),0)),0)) -> 0.061538462 | J11: 1666.67 | K11: =IF(E11<0,(H11*J11*-E11*(1+F11/100))/(E11+F11),(100*H11*J11*(100+F11))/(E11*F11-10000)) -> 975.97793 | L11: =IF(E11<0,((100-E11)*H11*J11)/(E11+F11),100*((100+E11)*H11*J11)/(E11*F11-10000)) -> 690.69207 | M11: =H11*J11 -> 60.06018 | N11: =IF(G11="F",(F11*J11)/(100+F11),IF(G11="U",IF(E11<0,(-E11*J11)/(100-E11),IF(E11>0,(100*J11)/(E11+100),0)),0)) -> 1000.002 | O11: =IF(AND(G11="F",E11<>""),(100*J11)/(100+F11),IF(G11="U",IF(E11<0,(100*J11)/(100-E11),IF(E11>0,(E11*J11)/(E11+100),0)),0)) -> 666.668 | P11: =I11*J11 -> 102.56431 | Q11: F | R11: F | S11: =IF((Q11="F"),IF(R11=G11,P11,0),IF(Q11="E",M11,0)) -> 102.56431 | X11: 45245 | Y11: {=SUM(_xlfn._xlws.FILTER(S:S,A:A=X11,0))} -> 0 | AA11: BetRivers | AB11: 0 | AC11: 1600.59
A12: 45244 | B12: Fanduel | C12: TheScore | D12: LeBron James Threes Made (O/U 1.5) | E12: -130 | F12: 135 | G12: F | H12: =IF(E12<0,100*(E12+F12)/(10000-200*E12-E12*F12),IF(E12>0,(E12*F12-10000)/(100*(E12+F12+200)),0)) -> 0.0093370682 | I12: =IF(E12<0,IF(G12="F",-100*(E12+F12)/(E12*(F12+100)),IF(G12="U",-(F12+E12)/(E12-100),0)),IF(E12>0,IF(G12="F",(E12*F12-10000)/(100*F12+10000),IF(G12="U",(E12*F12-10000)/(100*E12+10000),0)),0)) -> 0.016366612 | J12: 870.37 | K12: =IF(E12<0,(H12*J12*-E12*(1+F12/100))/(E12+F12),(100*H12*J12*(100+F12))/(E12*F12-10000)) -> 496.54162 | L12: =IF(E12<0,((100-E12)*H12*J12)/(E12+F12),100*((100+E12)*H12*J12)/(E12*F12-10000)) -> 373.82838 | M12: =H12*J12 -> 8.126704 | N12: =IF(G12="F",(F12*J12)/(100+F12),IF(G12="U",IF(E12<0,(-E12*J12)/(100-E12),IF(E12>0,(100*J12)/(E12+100),0)),0)) -> 499.99979 | O12: =IF(AND(G12="F",E12<>""),(100*J12)/(100+F12),IF(G12="U",IF(E12<0,(100*J12)/(100-E12),IF(E12>0,(E12*J12)/(E12+100),0)),0)) -> 370.37021 | P12: =I12*J12 -> 14.245008 | Q12: F | R12: F | S12: =IF((Q12="F"),IF(R12=G12,P12,0),IF(Q12="E",M12,0)) -> 14.245008 | X12: 45246 | Y12: {=SUM(_xlfn._xlws.FILTER(S:S,A:A=X12,0))} -> 0 | AA12: DraftKings | AB12: 0 | AC12: 3203.19
A13: 45254 | B13: Unibet | C13: Fanduel | D13: Damon Heta v Jules van Dongen | E13: -225 | F13: 250 | G13: U | H13: =IF(E13<0,100*(E13+F13)/(10000-200*E13-E13*F13),IF(E13>0,(E13*F13-10000)/(100*(E13+F13+200)),0)) -> 0.02247191 | I13: =IF(E13<0,IF(G13="F",-100*(E13+F13)/(E13*(F13+100)),IF(G13="U",-(F13+E13)/(E13-100),0)),IF(E13>0,IF(G13="F",(E13*F13-10000)/(100*F13+10000),IF(G13="U",(E13*F13-10000)/(100*E13+10000),0)),0)) -> 0.076923077 | J13: 102.48 | K13: =IF(E13<0,(H13*J13*-E13*(1+F13/100))/(E13+F13),(100*H13*J13*(100+F13))/(E13*F13-10000)) -> 72.542022 | L13: =IF(E13<0,((100-E13)*H13*J13)/(E13+F13),100*((100+E13)*H13*J13)/(E13*F13-10000)) -> 29.937978 | M13: =H13*J13 -> 2.3029213 | N13: =IF(G13="F",(F13*J13)/(100+F13),IF(G13="U",IF(E13<0,(-E13*J13)/(100-E13),IF(E13>0,(100*J13)/(E13+100),0)),0)) -> 70.947692 | O13: =IF(AND(G13="F",E13<>""),(100*J13)/(100+F13),IF(G13="U",IF(E13<0,(100*J13)/(100-E13),IF(E13>0,(E13*J13)/(E13+100),0)),0)) -> 31.532308 | P13: =I13*J13 -> 7.8830769 | Q13: F | R13: F | S13: =IF((Q13="F"),IF(R13=G13,P13,0),IF(Q13="E",M13,0)) -> 0 | X13: 45247 | Y13: {=SUM(_xlfn._xlws.FILTER(S:S,A:A=X13,0))} -> 0 | AA13: TonyBet | AB13: 0 | AC13: 0
A14: 45252 | B14: PokerStars | C14: Unibet | D14: Projekt Warsaw v Calcit Kamnik | E14: -700 | F14: 1800 | G14: F | H14: =IF(E14<0,100*(E14+F14)/(10000-200*E14-E14*F14),IF(E14>0,(E14*F14-10000)/(100*(E14+F14+200)),0)) -> 0.078014184 | I14: =IF(E14<0,IF(G14="F",-100*(E14+F14)/(E14*(F14+100)),IF(G14="U",-(F14+E14)/(E14-100),0)),IF(E14>0,IF(G14="F",(E14*F14-10000)/(100*F14+10000),IF(G14="U",(E14*F14-10000)/(100*E14+10000),0)),0)) -> 0.082706767 | J14: 440.43 | K14: =IF(E14<0,(H14*J14*-E14*(1+F14/100))/(E14+F14),(100*H14*J14*(100+F14))/(E14*F14-10000)) -> 415.44106 | L14: =IF(E14<0,((100-E14)*H14*J14)/(E14+F14),100*((100+E14)*H14*J14)/(E14*F14-10000)) -> 24.988936 | M14: =H14*J14 -> 34.359787 | N14: =IF(G14="F",(F14*J14)/(100+F14),IF(G14="U",IF(E14<0,(-E14*J14)/(100-E14),IF(E14>0,(100*J14)/(E14+100),0)),0)) -> 417.24947 | O14: =IF(AND(G14="F",E14<>""),(100*J14)/(100+F14),IF(G14="U",IF(E14<0,(100*J14)/(100-E14),IF(E14>0,(E14*J14)/(E14+100),0)),0)) -> 23.180526 | P14: =I14*J14 -> 36.426541 | Q14: E | R14: F | S14: =IF((Q14="F"),IF(R14=G14,P14,0),IF(Q14="E",M14,0)) -> 34.359787 | X14: 45248 | Y14: {=SUM(_xlfn._xlws.FILTER(S:S,A:A=X14,0))} -> 0 | AA14: BetVictor | AB14: 0 | AC14: 1846.33
A15: 45252 | B15: PokerStars | C15: Unibet | D15: Projekt Warsaw v Calcit Kamnik (Boosted) | E15: -700 | F15: 2800 | G15: F | H15: =IF(E15<0,100*(E15+F15)/(10000-200*E15-E15*F15),IF(E15>0,(E15*F15-10000)/(100*(E15+F15+200)),0)) -> 0.099526066 | I15: =IF(E15<0,IF(G15="F",-100*(E15+F15)/(E15*(F15+100)),IF(G15="U",-(F15+E15)/(E15-100),0)),IF(E15>0,IF(G15="F",(E15*F15-10000)/(100*F15+10000),IF(G15="U",(E15*F15-10000)/(100*E15+10000),0)),0)) -> 0.10344828 | J15: 470.85 | K15: =IF(E15<0,(H15*J15*-E15*(1+F15/100))/(E15+F15),(100*H15*J15*(100+F15))/(E15*F15-10000)) -> 452.99787 | L15: =IF(E15<0,((100-E15)*H15*J15)/(E15+F15),100*((100+E15)*H15*J15)/(E15*F15-10000)) -> 17.852133 | M15: =H15*J15 -> 46.861848 | N15: =IF(G15="F",(F15*J15)/(100+F15),IF(G15="U",IF(E15<0,(-E15*J15)/(100-E15),IF(E15>0,(100*J15)/(E15+100),0)),0)) -> 454.61379 | O15: =IF(AND(G15="F",E15<>""),(100*J15)/(100+F15),IF(G15="U",IF(E15<0,(100*J15)/(100-E15),IF(E15>0,(E15*J15)/(E15+100),0)),0)) -> 16.236207 | P15: =I15*J15 -> 48.708621 | Q15: E | R15: F | S15: =IF((Q15="F"),IF(R15=G15,P15,0),IF(Q15="E",M15,0)) -> 46.861848 | W15: WEEK 3 | X15: 45249 | Y15: {=SUM(_xlfn._xlws.FILTER(S:S,A:A=X15,0))} -> 0 | AA15: SportsInteraction | AB15: 0 | AC15: 0
A16: 45252 | B16: PokerStars | C16: Unibet | D16: Projekt Warsaw v Calcit Kamnik | E16: -700 | F16: 1400 | G16: F | H16: =IF(E16<0,100*(E16+F16)/(10000-200*E16-E16*F16),IF(E16>0,(E16*F16-10000)/(100*(E16+F16+200)),0)) -> 0.061946903 | I16: =IF(E16<0,IF(G16="F",-100*(E16+F16)/(E16*(F16+100)),IF(G16="U",-(F16+E16)/(E16-100),0)),IF(E16>0,IF(G16="F",(E16*F16-10000)/(100*F16+10000),IF(G16="U",(E16*F16-10000)/(100*E16+10000),0)),0)) -> 0.066666667 | J16: 201.69 | K16: =IF(E16<0,(H16*J16*-E16*(1+F16/100))/(E16+F16),(100*H16*J16*(100+F16))/(E16*F16-10000)) -> 187.41106 | L16: =IF(E16<0,((100-E16)*H16*J16)/(E16+F16),100*((100+E16)*H16*J16)/(E16*F16-10000)) -> 14.278938 | M16: =H16*J16 -> 12.494071 | N16: =IF(G16="F",(F16*J16)/(100+F16),IF(G16="U",IF(E16<0,(-E16*J16)/(100-E16),IF(E16>0,(100*J16)/(E16+100),0)),0)) -> 188.244 | O16: =IF(AND(G16="F",E16<>""),(100*J16)/(100+F16),IF(G16="U",IF(E16<0,(100*J16)/(100-E16),IF(E16>0,(E16*J16)/(E16+100),0)),0)) -> 13.446 | P16: =I16*J16 -> 13.446 | Q16: E | R16: F | S16: =IF((Q16="F"),IF(R16=G16,P16,0),IF(Q16="E",M16,0)) -> 12.494071 | W16: =SUM(Y15:Y21) -> 234.56103 | X16: 45250 | Y16: {=SUM(_xlfn._xlws.FILTER(S:S,A:A=X16,0))} -> 0 | AA16: BetMGM | AB16: 0 | AC16: 3829.73
A17: 45256 | B17: Unibet | C17: Betano | D17: Exeter Chiefs v Newcastle Falcons | E17: -225 | F17: 235 | G17: F | H17: =IF(E17<0,100*(E17+F17)/(10000-200*E17-E17*F17),IF(E17>0,(E17*F17-10000)/(100*(E17+F17+200)),0)) -> 0.0092699884 | I17: =IF(E17<0,IF(G17="F",-100*(E17+F17)/(E17*(F17+100)),IF(G17="U",-(F17+E17)/(E17-100),0)),IF(E17>0,IF(G17="F",(E17*F17-10000)/(100*F17+10000),IF(G17="U",(E17*F17-10000)/(100*E17+10000),0)),0)) -> 0.013266998 | J17: 500 | K17: =IF(E17<0,(H17*J17*-E17*(1+F17/100))/(E17+F17),(100*H17*J17*(100+F17))/(E17*F17-10000)) -> 349.36269 | L17: =IF(E17<0,((100-E17)*H17*J17)/(E17+F17),100*((100+E17)*H17*J17)/(E17*F17-10000)) -> 150.63731 | M17: =H17*J17 -> 4.6349942 | N17: =IF(G17="F",(F17*J17)/(100+F17),IF(G17="U",IF(E17<0,(-E17*J17)/(100-E17),IF(E17>0,(100*J17)/(E17+100),0)),0)) -> 350.74627 | O17: =IF(AND(G17="F",E17<>""),(100*J17)/(100+F17),IF(G17="U",IF(E17<0,(100*J17)/(100-E17),IF(E17>0,(E17*J17)/(E17+100),0)),0)) -> 149.25373 | P17: =I17*J17 -> 6.6334992 | Q17: E | R17: F | S17: =IF((Q17="F"),IF(R17=G17,P17,0),IF(Q17="E",M17,0)) -> 4.6349942 | X17: 45251 | Y17: {=SUM(_xlfn._xlws.FILTER(S:S,A:A=X17,0))} -> 0 | AA17: 888Sports | AB17: 0 | AC17: 0
A18: 45252 | B18: Fanduel | C18: Betano | D18: Chris Paul Assists (U/O 9.5) | E18: -102 | F18: 110 | G18: F | H18: =IF(E18<0,100*(E18+F18)/(10000-200*E18-E18*F18),IF(E18>0,(E18*F18-10000)/(100*(E18+F18+200)),0)) -> 0.019221528 | I18: =IF(E18<0,IF(G18="F",-100*(E18+F18)/(E18*(F18+100)),IF(G18="U",-(F18+E18)/(E18-100),0)),IF(E18>0,IF(G18="F",(E18*F18-10000)/(100*F18+10000),IF(G18="U",(E18*F18-10000)/(100*E18+10000),0)),0)) -> 0.037348273 | J18: 412.08 | K18: =IF(E18<0,(H18*J18*-E18*(1+F18/100))/(E18+F18),(100*H18*J18*(100+F18))/(E18*F18-10000)) -> 212.07962 | L18: =IF(E18<0,((100-E18)*H18*J18)/(E18+F18),100*((100+E18)*H18*J18)/(E18*F18-10000)) -> 200.00038 | M18: =H18*J18 -> 7.9208073 | N18: =IF(G18="F",(F18*J18)/(100+F18),IF(G18="U",IF(E18<0,(-E18*J18)/(100-E18),IF(E18>0,(100*J18)/(E18+100),0)),0)) -> 215.85143 | O18: =IF(AND(G18="F",E18<>""),(100*J18)/(100+F18),IF(G18="U",IF(E18<0,(100*J18)/(100-E18),IF(E18>0,(E18*J18)/(E18+100),0)),0)) -> 196.22857 | P18: =I18*J18 -> 15.390476 | Q18: E | R18: F | S18: =IF((Q18="F"),IF(R18=G18,P18,0),IF(Q18="E",M18,0)) -> 7.9208073 | X18: 45252 | Y18: {=SUM(_xlfn._xlws.FILTER(S:S,A:A=X18,0))} -> 149.52236 | AA18: Pointsbet | AB18: 0 | AC18: 190.88
A19: 45252 | B19: Fanduel | C19: Betano | D19: Fenerbahce v CS Sepsi CIS 1st Q Total (O/U 38.5) | E19: 100 | F19: 107 | G19: F | H19: =IF(E19<0,100*(E19+F19)/(10000-200*E19-E19*F19),IF(E19>0,(E19*F19-10000)/(100*(E19+F19+200)),0)) -> 0.017199017 | I19: =IF(E19<0,IF(G19="F",-100*(E19+F19)/(E19*(F19+100)),IF(G19="U",-(F19+E19)/(E19-100),0)),IF(E19>0,IF(G19="F",(E19*F19-10000)/(100*F19+10000),IF(G19="U",(E19*F19-10000)/(100*E19+10000),0)),0)) -> 0.033816425 | J19: 414 | K19: =IF(E19<0,(H19*J19*-E19*(1+F19/100))/(E19+F19),(100*H19*J19*(100+F19))/(E19*F19-10000)) -> 210.5602 | L19: =IF(E19<0,((100-E19)*H19*J19)/(E19+F19),100*((100+E19)*H19*J19)/(E19*F19-10000)) -> 203.4398 | M19: =H19*J19 -> 7.1203931 | N19: =IF(G19="F",(F19*J19)/(100+F19),IF(G19="U",IF(E19<0,(-E19*J19)/(100-E19),IF(E19>0,(100*J19)/(E19+100),0)),0)) -> 214 | O19: =IF(AND(G19="F",E19<>""),(100*J19)/(100+F19),IF(G19="U",IF(E19<0,(100*J19)/(100-E19),IF(E19>0,(E19*J19)/(E19+100),0)),0)) -> 200 | P19: =I19*J19 -> 14 | Q19: F | R19: F | S19: =IF((Q19="F"),IF(R19=G19,P19,0),IF(Q19="E",M19,0)) -> 14 | X19: 45253 | Y19: {=SUM(_xlfn._xlws.FILTER(S:S,A:A=X19,0))} -> 0 | AA19: Pinnacle | AB19: 0 | AC19: 0
A20: 45252 | B20: Fanduel | C20: Betano | D20: Grant Williams Rebounds (U/O 3.5) | E20: -114 | F20: 118 | G20: F | H20: =IF(E20<0,100*(E20+F20)/(10000-200*E20-E20*F20),IF(E20>0,(E20*F20-10000)/(100*(E20+F20+200)),0)) -> 0.0086482747 | I20: =IF(E20<0,IF(G20="F",-100*(E20+F20)/(E20*(F20+100)),IF(G20="U",-(F20+E20)/(E20-100),0)),IF(E20>0,IF(G20="F",(E20*F20-10000)/(100*F20+10000),IF(G20="U",(E20*F20-10000)/(100*E20+10000),0)),0)) -> 0.016095284 | J20: 432.26 | K20: =IF(E20<0,(H20*J20*-E20*(1+F20/100))/(E20+F20),(100*H20*J20*(100+F20))/(E20*F20-10000)) -> 232.26078 | L20: =IF(E20<0,((100-E20)*H20*J20)/(E20+F20),100*((100+E20)*H20*J20)/(E20*F20-10000)) -> 199.99922 | M20: =H20*J20 -> 3.7383032 | N20: =IF(G20="F",(F20*J20)/(100+F20),IF(G20="U",IF(E20<0,(-E20*J20)/(100-E20),IF(E20>0,(100*J20)/(E20+100),0)),0)) -> 233.9756 | O20: =IF(AND(G20="F",E20<>""),(100*J20)/(100+F20),IF(G20="U",IF(E20<0,(100*J20)/(100-E20),IF(E20>0,(E20*J20)/(E20+100),0)),0)) -> 198.2844 | P20: =I20*J20 -> 6.9573475 | Q20: E | R20: F | S20: =IF((Q20="F"),IF(R20=G20,P20,0),IF(Q20="E",M20,0)) -> 3.7383032 | X20: 45254 | Y20: {=SUM(_xlfn._xlws.FILTER(S:S,A:A=X20,0))} -> 58.310627 | AA20: Partypoker | AB20: 0 | AC20: 113.22
A21: 45252 | B21: Bet365 | C21: Betano | D21: Kelly Olynyk Rebounds (O/U 5.5) | E21: 100 | F21: 112 | G21: F | H21: =IF(E21<0,100*(E21+F21)/(10000-200*E21-E21*F21),IF(E21>0,(E21*F21-10000)/(100*(E21+F21+200)),0)) -> 0.029126214 | I21: =IF(E21<0,IF(G21="F",-100*(E21+F21)/(E21*(F21+100)),IF(G21="U",-(F21+E21)/(E21-100),0)),IF(E21>0,IF(G21="F",(E21*F21-10000)/(100*F21+10000),IF(G21="U",(E21*F21-10000)/(100*E21+10000),0)),0)) -> 0.056603774 | J21: 424 | K21: =IF(E21<0,(H21*J21*-E21*(1+F21/100))/(E21+F21),(100*H21*J21*(100+F21))/(E21*F21-10000)) -> 218.17476 | L21: =IF(E21<0,((100-E21)*H21*J21)/(E21+F21),100*((100+E21)*H21*J21)/(E21*F21-10000)) -> 205.82524 | M21: =H21*J21 -> 12.349515 | N21: =IF(G21="F",(F21*J21)/(100+F21),IF(G21="U",IF(E21<0,(-E21*J21)/(100-E21),IF(E21>0,(100*J21)/(E21+100),0)),0)) -> 224 | O21: =IF(AND(G21="F",E21<>""),(100*J21)/(100+F21),IF(G21="U",IF(E21<0,(100*J21)/(100-E21),IF(E21>0,(E21*J21)/(E21+100),0)),0)) -> 200 | P21: =I21*J21 -> 24 | Q21: F | R21: F | S21: =IF((Q21="F"),IF(R21=G21,P21,0),IF(Q21="E",M21,0)) -> 24 | X21: 45255 | Y21: {=SUM(_xlfn._xlws.FILTER(S:S,A:A=X21,0))} -> 26.728049 | AA21: CASH | AB21: 0 | AC21: 500
A22: 45252 | B22: Fanduel | C22: Betano | D22: Moses Moody Rebounds (O/U 2.5) | E22: -122 | F22: 125 | G22: F | H22: =IF(E22<0,100*(E22+F22)/(10000-200*E22-E22*F22),IF(E22>0,(E22*F22-10000)/(100*(E22+F22+200)),0)) -> 0.0060422961 | I22: =IF(E22<0,IF(G22="F",-100*(E22+F22)/(E22*(F22+100)),IF(G22="U",-(F22+E22)/(E22-100),0)),IF(E22>0,IF(G22="F",(E22*F22-10000)/(100*F22+10000),IF(G22="U",(E22*F22-10000)/(100*E22+10000),0)),0)) -> 0.010928962 | J22: 562.5 | K22: =IF(E22<0,(H22*J22*-E22*(1+F22/100))/(E22+F22),(100*H22*J22*(100+F22))/(E22*F22-10000)) -> 310.98943 | L22: =IF(E22<0,((100-E22)*H22*J22)/(E22+F22),100*((100+E22)*H22*J22)/(E22*F22-10000)) -> 251.51057 | M22: =H22*J22 -> 3.3987915 | N22: =IF(G22="F",(F22*J22)/(100+F22),IF(G22="U",IF(E22<0,(-E22*J22)/(100-E22),IF(E22>0,(100*J22)/(E22+100),0)),0)) -> 312.5 | O22: =IF(AND(G22="F",E22<>""),(100*J22)/(100+F22),IF(G22="U",IF(E22<0,(100*J22)/(100-E22),IF(E22>0,(E22*J22)/(E22+100),0)),0)) -> 250 | P22: =I22*J22 -> 6.147541 | Q22: F | R22: F | S22: =IF((Q22="F"),IF(R22=G22,P22,0),IF(Q22="E",M22,0)) -> 6.147541 | W22: WEEK 4 | X22: 45256 | Y22: {=SUM(_xlfn._xlws.FILTER(S:S,A:A=X22,0))} -> 48.625924 | AA22: In transit | AB22: 0 | AC22: 0
A23: 45255 | B23: DraftKings | C23: Fanduel | D23: Kyle Mccord Passing TDs (U/O 1.5) | E23: -115 | F23: 120 | G23: F | H23: =IF(E23<0,100*(E23+F23)/(10000-200*E23-E23*F23),IF(E23>0,(E23*F23-10000)/(100*(E23+F23+200)),0)) -> 0.010683761 | I23: =IF(E23<0,IF(G23="F",-100*(E23+F23)/(E23*(F23+100)),IF(G23="U",-(F23+E23)/(E23-100),0)),IF(E23>0,IF(G23="F",(E23*F23-10000)/(100*F23+10000),IF(G23="U",(E23*F23-10000)/(100*E23+10000),0)),0)) -> 0.019762846 | J23: 660 | K23: =IF(E23<0,(H23*J23*-E23*(1+F23/100))/(E23+F23),(100*H23*J23*(100+F23))/(E23*F23-10000)) -> 356.79487 | L23: =IF(E23<0,((100-E23)*H23*J23)/(E23+F23),100*((100+E23)*H23*J23)/(E23*F23-10000)) -> 303.20513 | M23: =H23*J23 -> 7.0512821 | N23: =IF(G23="F",(F23*J23)/(100+F23),IF(G23="U",IF(E23<0,(-E23*J23)/(100-E23),IF(E23>0,(100*J23)/(E23+100),0)),0)) -> 360 | O23: =IF(AND(G23="F",E23<>""),(100*J23)/(100+F23),IF(G23="U",IF(E23<0,(100*J23)/(100-E23),IF(E23>0,(E23*J23)/(E23+100),0)),0)) -> 300 | P23: =I23*J23 -> 13.043478 | Q23: F | R23: U | S23: =IF((Q23="F"),IF(R23=G23,P23,0),IF(Q23="E",M23,0)) -> 0 | W23: =SUM(Y22:Y28) -> 312.9251 | X23: 45257 | Y23: {=SUM(_xlfn._xlws.FILTER(S:S,A:A=X23,0))} -> 0 | AC23: =SUM(AC2:AC22) -> 29572.54
A24: 45255 | B24: Fanduel | C24: Unibet | D24: Michael Penix Jr. Passing TDs (U/O 3.5) | E24: -205 | F24: 240 | G24: F | H24: =IF(E24<0,100*(E24+F24)/(10000-200*E24-E24*F24),IF(E24>0,(E24*F24-10000)/(100*(E24+F24+200)),0)) -> 0.03493014 | I24: =IF(E24<0,IF(G24="F",-100*(E24+F24)/(E24*(F24+100)),IF(G24="U",-(F24+E24)/(E24-100),0)),IF(E24>0,IF(G24="F",(E24*F24-10000)/(100*F24+10000),IF(G24="U",(E24*F24-10000)/(100*E24+10000),0)),0)) -> 0.050215208 | J24: 532.27 | K24: =IF(E24<0,(H24*J24*-E24*(1+F24/100))/(E24+F24),(100*H24*J24*(100+F24))/(E24*F24-10000)) -> 370.25169 | L24: =IF(E24<0,((100-E24)*H24*J24)/(E24+F24),100*((100+E24)*H24*J24)/(E24*F24-10000)) -> 162.01831 | M24: =H24*J24 -> 18.592265 | N24: =IF(G24="F",(F24*J24)/(100+F24),IF(G24="U",IF(E24<0,(-E24*J24)/(100-E24),IF(E24>0,(100*J24)/(E24+100),0)),0)) -> 375.72 | O24: =IF(AND(G24="F",E24<>""),(100*J24)/(100+F24),IF(G24="U",IF(E24<0,(100*J24)/(100-E24),IF(E24>0,(E24*J24)/(E24+100),0)),0)) -> 156.55 | P24: =I24*J24 -> 26.728049 | Q24: F | R24: F | S24: =IF((Q24="F"),IF(R24=G24,P24,0),IF(Q24="E",M24,0)) -> 26.728049 | X24: 45258 | Y24: {=SUM(_xlfn._xlws.FILTER(S:S,A:A=X24,0))} -> 0
A25: 45256 | B25: Unibet | C25: Fanduel | D25: Exeter Chiefs v Newcastle Falcons | E25: -225 | F25: 245 | G25: F | H25: =IF(E25<0,100*(E25+F25)/(10000-200*E25-E25*F25),IF(E25>0,(E25*F25-10000)/(100*(E25+F25+200)),0)) -> 0.01816118 | I25: =IF(E25<0,IF(G25="F",-100*(E25+F25)/(E25*(F25+100)),IF(G25="U",-(F25+E25)/(E25-100),0)),IF(E25>0,IF(G25="F",(E25*F25-10000)/(100*F25+10000),IF(G25="U",(E25*F25-10000)/(100*E25+10000),0)),0)) -> 0.025764895 | J25: 61.64 | K25: =IF(E25<0,(H25*J25*-E25*(1+F25/100))/(E25+F25),(100*H25*J25*(100+F25))/(E25*F25-10000)) -> 43.448854 | L25: =IF(E25<0,((100-E25)*H25*J25)/(E25+F25),100*((100+E25)*H25*J25)/(E25*F25-10000)) -> 18.191146 | M25: =H25*J25 -> 1.1194552 | N25: =IF(G25="F",(F25*J25)/(100+F25),IF(G25="U",IF(E25<0,(-E25*J25)/(100-E25),IF(E25>0,(100*J25)/(E25+100),0)),0)) -> 43.773333 | O25: =IF(AND(G25="F",E25<>""),(100*J25)/(100+F25),IF(G25="U",IF(E25<0,(100*J25)/(100-E25),IF(E25>0,(E25*J25)/(E25+100),0)),0)) -> 17.866667 | P25: =I25*J25 -> 1.5881481 | Q25: E | R25: F | S25: =IF((Q25="F"),IF(R25=G25,P25,0),IF(Q25="E",M25,0)) -> 1.1194552 | X25: 45259 | Y25: {=SUM(_xlfn._xlws.FILTER(S:S,A:A=X25,0))} -> 48.019449 | AA25: CHECKS
A26: 45256 | B26: Fanduel | C26: Bet365 | D26: Zay Flowers Total Receptions (O/U 4.5) | E26: -130 | F26: 140 | G26: F | H26: =IF(E26<0,100*(E26+F26)/(10000-200*E26-E26*F26),IF(E26>0,(E26*F26-10000)/(100*(E26+F26+200)),0)) -> 0.018450185 | I26: =IF(E26<0,IF(G26="F",-100*(E26+F26)/(E26*(F26+100)),IF(G26="U",-(F26+E26)/(E26-100),0)),IF(E26>0,IF(G26="F",(E26*F26-10000)/(100*F26+10000),IF(G26="U",(E26*F26-10000)/(100*E26+10000),0)),0)) -> 0.032051282 | J26: 720 | K26: =IF(E26<0,(H26*J26*-E26*(1+F26/100))/(E26+F26),(100*H26*J26*(100+F26))/(E26*F26-10000)) -> 414.46494 | L26: =IF(E26<0,((100-E26)*H26*J26)/(E26+F26),100*((100+E26)*H26*J26)/(E26*F26-10000)) -> 305.53506 | M26: =H26*J26 -> 13.284133 | N26: =IF(G26="F",(F26*J26)/(100+F26),IF(G26="U",IF(E26<0,(-E26*J26)/(100-E26),IF(E26>0,(100*J26)/(E26+100),0)),0)) -> 420 | O26: =IF(AND(G26="F",E26<>""),(100*J26)/(100+F26),IF(G26="U",IF(E26<0,(100*J26)/(100-E26),IF(E26>0,(E26*J26)/(E26+100),0)),0)) -> 300 | P26: =I26*J26 -> 23.076923 | Q26: F | R26: F | S26: =IF((Q26="F"),IF(R26=G26,P26,0),IF(Q26="E",M26,0)) -> 23.076923 | X26: 45260 | Y26: {=SUM(_xlfn._xlws.FILTER(S:S,A:A=X26,0))} -> 53.616133 | AA26: Dec 9 2023 | AB26: 21273.48
A27: 45256 | B27: Fanduel | C27: Bet365 | D27: Zay Flowers Total Receptions (O/U 4.5) | E27: -130 | F27: 140 | G27: F | H27: =IF(E27<0,100*(E27+F27)/(10000-200*E27-E27*F27),IF(E27>0,(E27*F27-10000)/(100*(E27+F27+200)),0)) -> 0.018450185 | I27: =IF(E27<0,IF(G27="F",-100*(E27+F27)/(E27*(F27+100)),IF(G27="U",-(F27+E27)/(E27-100),0)),IF(E27>0,IF(G27="F",(E27*F27-10000)/(100*F27+10000),IF(G27="U",(E27*F27-10000)/(100*E27+10000),0)),0)) -> 0.032051282 | J27: 617.59 | K27: =IF(E27<0,(H27*J27*-E27*(1+F27/100))/(E27+F27),(100*H27*J27*(100+F27))/(E27*F27-10000)) -> 355.51306 | L27: =IF(E27<0,((100-E27)*H27*J27)/(E27+F27),100*((100+E27)*H27*J27)/(E27*F27-10000)) -> 262.07694 | M27: =H27*J27 -> 11.394649 | N27: =IF(G27="F",(F27*J27)/(100+F27),IF(G27="U",IF(E27<0,(-E27*J27)/(100-E27),IF(E27>0,(100*J27)/(E27+100),0)),0)) -> 360.26083 | O27: =IF(AND(G27="F",E27<>""),(100*J27)/(100+F27),IF(G27="U",IF(E27<0,(100*J27)/(100-E27),IF(E27>0,(E27*J27)/(E27+100),0)),0)) -> 257.32917 | P27: =I27*J27 -> 19.794551 | Q27: F | R27: F | S27: =IF((Q27="F"),IF(R27=G27,P27,0),IF(Q27="E",M27,0)) -> 19.794551 | X27: 45261 | Y27: {=SUM(_xlfn._xlws.FILTER(S:S,A:A=X27,0))} -> 0 | AA27: Dec 21 2023 | AB27: 21950.72
A28: 45258 | B28: Fanduel | C28: Bet365 | D28: Domantas Sabonis Points (O/U 19.5) | E28: -105 | F28: 110 | G28: F | H28: =IF(E28<0,100*(E28+F28)/(10000-200*E28-E28*F28),IF(E28>0,(E28*F28-10000)/(100*(E28+F28+200)),0)) -> 0.011750881 | I28: =IF(E28<0,IF(G28="F",-100*(E28+F28)/(E28*(F28+100)),IF(G28="U",-(F28+E28)/(E28-100),0)),IF(E28>0,IF(G28="F",(E28*F28-10000)/(100*F28+10000),IF(G28="U",(E28*F28-10000)/(100*E28+10000),0)),0)) -> 0.022675737 | J28: 1050 | K28: =IF(E28<0,(H28*J28*-E28*(1+F28/100))/(E28+F28),(100*H28*J28*(100+F28))/(E28*F28-10000)) -> 544.12456 | L28: =IF(E28<0,((100-E28)*H28*J28)/(E28+F28),100*((100+E28)*H28*J28)/(E28*F28-10000)) -> 505.87544 | M28: =H28*J28 -> 12.338425 | N28: =IF(G28="F",(F28*J28)/(100+F28),IF(G28="U",IF(E28<0,(-E28*J28)/(100-E28),IF(E28>0,(100*J28)/(E28+100),0)),0)) -> 550 | O28: =IF(AND(G28="F",E28<>""),(100*J28)/(100+F28),IF(G28="U",IF(E28<0,(100*J28)/(100-E28),IF(E28>0,(E28*J28)/(E28+100),0)),0)) -> 500 | P28: =I28*J28 -> 23.809524 | Q28: F | R28: U | S28: =IF((Q28="F"),IF(R28=G28,P28,0),IF(Q28="E",M28,0)) -> 0 | X28: 45262 | Y28: {=SUM(_xlfn._xlws.FILTER(S:S,A:A=X28,0))} -> 162.66359 | AA28: Jan 15 2023 | AB28: 29572.54
A29: 45259 | B29: Bet365 | C29: Unibet | D29: Alex Ovechkin PowerPlay Points (U/O 0.5) | E29: -175 | F29: 185 | G29: F | H29: =IF(E29<0,100*(E29+F29)/(10000-200*E29-E29*F29),IF(E29>0,(E29*F29-10000)/(100*(E29+F29+200)),0)) -> 0.012924071 | I29: =IF(E29<0,IF(G29="F",-100*(E29+F29)/(E29*(F29+100)),IF(G29="U",-(F29+E29)/(E29-100),0)),IF(E29>0,IF(G29="F",(E29*F29-10000)/(100*F29+10000),IF(G29="U",(E29*F29-10000)/(100*E29+10000),0)),0)) -> 0.020050125 | J29: 68.8 | K29: =IF(E29<0,(H29*J29*-E29*(1+F29/100))/(E29+F29),(100*H29*J29*(100+F29))/(E29*F29-10000)) -> 44.347658 | L29: =IF(E29<0,((100-E29)*H29*J29)/(E29+F29),100*((100+E29)*H29*J29)/(E29*F29-10000)) -> 24.452342 | M29: =H29*J29 -> 0.88917609 | N29: =IF(G29="F",(F29*J29)/(100+F29),IF(G29="U",IF(E29<0,(-E29*J29)/(100-E29),IF(E29>0,(100*J29)/(E29+100),0)),0)) -> 44.659649 | O29: =IF(AND(G29="F",E29<>""),(100*J29)/(100+F29),IF(G29="U",IF(E29<0,(100*J29)/(100-E29),IF(E29>0,(E29*J29)/(E29+100),0)),0)) -> 24.140351 | P29: =I29*J29 -> 1.3794486 | Q29: F | R29: F | S29: =IF((Q29="F"),IF(R29=G29,P29,0),IF(Q29="E",M29,0)) -> 1.3794486 | W29: WEEK 5 | X29: 45263 | Y29: {=SUM(_xlfn._xlws.FILTER(S:S,A:A=X29,0))} -> 93.623167
A30: 45263 | B30: Fanduel | C30: Bet365 | D30: Russell Wilson Passing TDs (U/O 1.5) | E30: -122 | F30: 130 | G30: F | H30: =IF(E30<0,100*(E30+F30)/(10000-200*E30-E30*F30),IF(E30>0,(E30*F30-10000)/(100*(E30+F30+200)),0)) -> 0.01591723 | I30: =IF(E30<0,IF(G30="F",-100*(E30+F30)/(E30*(F30+100)),IF(G30="U",-(F30+E30)/(E30-100),0)),IF(E30>0,IF(G30="F",(E30*F30-10000)/(100*F30+10000),IF(G30="U",(E30*F30-10000)/(100*E30+10000),0)),0)) -> 0.028510335 | J30: 1391.5 | K30: =IF(E30<0,(H30*J30*-E30*(1+F30/100))/(E30+F30),(100*H30*J30*(100+F30))/(E30*F30-10000)) -> 776.87008 | L30: =IF(E30<0,((100-E30)*H30*J30)/(E30+F30),100*((100+E30)*H30*J30)/(E30*F30-10000)) -> 614.62992 | M30: =H30*J30 -> 22.148826 | N30: =IF(G30="F",(F30*J30)/(100+F30),IF(G30="U",IF(E30<0,(-E30*J30)/(100-E30),IF(E30>0,(100*J30)/(E30+100),0)),0)) -> 786.5 | O30: =IF(AND(G30="F",E30<>""),(100*J30)/(100+F30),IF(G30="U",IF(E30<0,(100*J30)/(100-E30),IF(E30>0,(E30*J30)/(E30+100),0)),0)) -> 605 | P30: =I30*J30 -> 39.672131 | Q30: F | R30: F | S30: =IF((Q30="F"),IF(R30=G30,P30,0),IF(Q30="E",M30,0)) -> 39.672131 | W30: =SUM(Y29:Y35) -> 786.07359 | X30: 45264 | Y30: {=SUM(_xlfn._xlws.FILTER(S:S,A:A=X30,0))} -> 0
A31: 45259 | B31: Betano | C31: DraftKings | D31: USC v Eastern Washington | E31: -1250 | F31: 2500 | G31: F | H31: =IF(E31<0,100*(E31+F31)/(10000-200*E31-E31*F31),IF(E31>0,(E31*F31-10000)/(100*(E31+F31+200)),0)) -> 0.036927622 | I31: =IF(E31<0,IF(G31="F",-100*(E31+F31)/(E31*(F31+100)),IF(G31="U",-(F31+E31)/(E31-100),0)),IF(E31>0,IF(G31="F",(E31*F31-10000)/(100*F31+10000),IF(G31="U",(E31*F31-10000)/(100*E31+10000),0)),0)) -> 0.038461538 | J31: 1212.64 | K31: =IF(E31<0,(H31*J31*-E31*(1+F31/100))/(E31+F31),(100*H31*J31*(100+F31))/(E31*F31-10000)) -> 1164.2777 | L31: =IF(E31<0,((100-E31)*H31*J31)/(E31+F31),100*((100+E31)*H31*J31)/(E31*F31-10000)) -> 48.362304 | M31: =H31*J31 -> 44.779911 | N31: =IF(G31="F",(F31*J31)/(100+F31),IF(G31="U",IF(E31<0,(-E31*J31)/(100-E31),IF(E31>0,(100*J31)/(E31+100),0)),0)) -> 1166 | O31: =IF(AND(G31="F",E31<>""),(100*J31)/(100+F31),IF(G31="U",IF(E31<0,(100*J31)/(100-E31),IF(E31>0,(E31*J31)/(E31+100),0)),0)) -> 46.64 | P31: =I31*J31 -> 46.64 | Q31: F | R31: F | S31: =IF((Q31="F"),IF(R31=G31,P31,0),IF(Q31="E",M31,0)) -> 46.64 | X31: 45265 | Y31: {=SUM(_xlfn._xlws.FILTER(S:S,A:A=X31,0))} -> 98.491175
A32: 45263 | B32: Betano | C32: DraftKings | D32: Aston Villa/Bournemouth Total Cards (O/U 4.5) | E32: -110 | F32: 115 | G32: F | H32: =IF(E32<0,100*(E32+F32)/(10000-200*E32-E32*F32),IF(E32>0,(E32*F32-10000)/(100*(E32+F32+200)),0)) -> 0.011198208 | I32: =IF(E32<0,IF(G32="F",-100*(E32+F32)/(E32*(F32+100)),IF(G32="U",-(F32+E32)/(E32-100),0)),IF(E32>0,IF(G32="F",(E32*F32-10000)/(100*F32+10000),IF(G32="U",(E32*F32-10000)/(100*E32+10000),0)),0)) -> 0.021141649 | J32: 934.79 | K32: =IF(E32<0,(H32*J32*-E32*(1+F32/100))/(E32+F32),(100*H32*J32*(100+F32))/(E32*F32-10000)) -> 495.13513 | L32: =IF(E32<0,((100-E32)*H32*J32)/(E32+F32),100*((100+E32)*H32*J32)/(E32*F32-10000)) -> 439.65487 | M32: =H32*J32 -> 10.467973 | N32: =IF(G32="F",(F32*J32)/(100+F32),IF(G32="U",IF(E32<0,(-E32*J32)/(100-E32),IF(E32>0,(100*J32)/(E32+100),0)),0)) -> 500.00395 | O32: =IF(AND(G32="F",E32<>""),(100*J32)/(100+F32),IF(G32="U",IF(E32<0,(100*J32)/(100-E32),IF(E32>0,(E32*J32)/(E32+100),0)),0)) -> 434.78605 | P32: =I32*J32 -> 19.763002 | Q32: F | R32: F | S32: =IF((Q32="F"),IF(R32=G32,P32,0),IF(Q32="E",M32,0)) -> 19.763002 | X32: 45266 | Y32: {=SUM(_xlfn._xlws.FILTER(S:S,A:A=X32,0))} -> 238.07328
A33: 45260 | B33: Bet365 | C33: BetRivers | D33: Alex Ovechkin PowerPlay Points (U/O 0.5) | E33: -160 | F33: 185 | G33: F | H33: =IF(E33<0,100*(E33+F33)/(10000-200*E33-E33*F33),IF(E33>0,(E33*F33-10000)/(100*(E33+F33+200)),0)) -> 0.034916201 | I33: =IF(E33<0,IF(G33="F",-100*(E33+F33)/(E33*(F33+100)),IF(G33="U",-(F33+E33)/(E33-100),0)),IF(E33>0,IF(G33="F",(E33*F33-10000)/(100*F33+10000),IF(G33="U",(E33*F33-10000)/(100*E33+10000),0)),0)) -> 0.054824561 | J33: 1143.47 | K33: =IF(E33<0,(H33*J33*-E33*(1+F33/100))/(E33+F33),(100*H33*J33*(100+F33))/(E33*F33-10000)) -> 728.24346 | L33: =IF(E33<0,((100-E33)*H33*J33)/(E33+F33),100*((100+E33)*H33*J33)/(E33*F33-10000)) -> 415.22654 | M33: =H33*J33 -> 39.925628 | N33: =IF(G33="F",(F33*J33)/(100+F33),IF(G33="U",IF(E33<0,(-E33*J33)/(100-E33),IF(E33>0,(100*J33)/(E33+100),0)),0)) -> 742.25246 | O33: =IF(AND(G33="F",E33<>""),(100*J33)/(100+F33),IF(G33="U",IF(E33<0,(100*J33)/(100-E33),IF(E33>0,(E33*J33)/(E33+100),0)),0)) -> 401.21754 | P33: =I33*J33 -> 62.690241 | Q33: F | R33: U | S33: =IF((Q33="F"),IF(R33=G33,P33,0),IF(Q33="E",M33,0)) -> 0 | X33: 45267 | Y33: {=SUM(_xlfn._xlws.FILTER(S:S,A:A=X33,0))} -> 291.92171
A34: 45260 | B34: Bet365 | C34: BetRivers | D34: Connor McDavid PowerPlay Points (O/U 0.5) | E34: 100 | F34: 110 | G34: F | H34: =IF(E34<0,100*(E34+F34)/(10000-200*E34-E34*F34),IF(E34>0,(E34*F34-10000)/(100*(E34+F34+200)),0)) -> 0.024390244 | I34: =IF(E34<0,IF(G34="F",-100*(E34+F34)/(E34*(F34+100)),IF(G34="U",-(F34+E34)/(E34-100),0)),IF(E34>0,IF(G34="F",(E34*F34-10000)/(100*F34+10000),IF(G34="U",(E34*F34-10000)/(100*E34+10000),0)),0)) -> 0.047619048 | J34: 616.6 | K34: =IF(E34<0,(H34*J34*-E34*(1+F34/100))/(E34+F34),(100*H34*J34*(100+F34))/(E34*F34-10000)) -> 315.81951 | L34: =IF(E34<0,((100-E34)*H34*J34)/(E34+F34),100*((100+E34)*H34*J34)/(E34*F34-10000)) -> 300.78049 | M34: =H34*J34 -> 15.039024 | N34: =IF(G34="F",(F34*J34)/(100+F34),IF(G34="U",IF(E34<0,(-E34*J34)/(100-E34),IF(E34>0,(100*J34)/(E34+100),0)),0)) -> 322.98095 | O34: =IF(AND(G34="F",E34<>""),(100*J34)/(100+F34),IF(G34="U",IF(E34<0,(100*J34)/(100-E34),IF(E34>0,(E34*J34)/(E34+100),0)),0)) -> 293.61905 | P34: =I34*J34 -> 29.361905 | Q34: E | R34: F | S34: =IF((Q34="F"),IF(R34=G34,P34,0),IF(Q34="E",M34,0)) -> 15.039024 | X34: 45268 | Y34: {=SUM(_xlfn._xlws.FILTER(S:S,A:A=X34,0))} -> 25.274725
A35: 45260 | B35: Unibet | C35: Bet365 | D35: Troy Terry Shots on Goal (U/O 2.5) | E35: -139 | F35: 150 | G35: F | H35: =IF(E35<0,100*(E35+F35)/(10000-200*E35-E35*F35),IF(E35>0,(E35*F35-10000)/(100*(E35+F35+200)),0)) -> 0.018755328 | I35: =IF(E35<0,IF(G35="F",-100*(E35+F35)/(E35*(F35+100)),IF(G35="U",-(F35+E35)/(E35-100),0)),IF(E35>0,IF(G35="F",(E35*F35-10000)/(100*F35+10000),IF(G35="U",(E35*F35-10000)/(100*E35+10000),0)),0)) -> 0.031654676 | J35: 207.35 | K35: =IF(E35<0,(H35*J35*-E35*(1+F35/100))/(E35+F35),(100*H35*J35*(100+F35))/(E35*F35-10000)) -> 122.85443 | L35: =IF(E35<0,((100-E35)*H35*J35)/(E35+F35),100*((100+E35)*H35*J35)/(E35*F35-10000)) -> 84.495567 | M35: =H35*J35 -> 3.8889173 | N35: =IF(G35="F",(F35*J35)/(100+F35),IF(G35="U",IF(E35<0,(-E35*J35)/(100-E35),IF(E35>0,(100*J35)/(E35+100),0)),0)) -> 124.41 | O35: =IF(AND(G35="F",E35<>""),(100*J35)/(100+F35),IF(G35="U",IF(E35<0,(100*J35)/(100-E35),IF(E35>0,(E35*J35)/(E35+100),0)),0)) -> 82.94 | P35: =I35*J35 -> 6.5635971 | Q35: F | R35: U | S35: =IF((Q35="F"),IF(R35=G35,P35,0),IF(Q35="E",M35,0)) -> 0 | X35: 45269 | Y35: {=SUM(_xlfn._xlws.FILTER(S:S,A:A=X35,0))} -> 38.68954
A36: 45260 | B36: Betano | C36: Fanduel | D36: Mike Conley Assists (U/O 7.5) | E36: -143 | F36: 152 | G36: F | H36: =IF(E36<0,100*(E36+F36)/(10000-200*E36-E36*F36),IF(E36>0,(E36*F36-10000)/(100*(E36+F36+200)),0)) -> 0.014916468 | I36: =IF(E36<0,IF(G36="F",-100*(E36+F36)/(E36*(F36+100)),IF(G36="U",-(F36+E36)/(E36-100),0)),IF(E36>0,IF(G36="F",(E36*F36-10000)/(100*F36+10000),IF(G36="U",(E36*F36-10000)/(100*E36+10000),0)),0)) -> 0.024975025 | J36: 927.23 | K36: =IF(E36<0,(H36*J36*-E36*(1+F36/100))/(E36+F36),(100*H36*J36*(100+F36))/(E36*F36-10000)) -> 553.7931 | L36: =IF(E36<0,((100-E36)*H36*J36)/(E36+F36),100*((100+E36)*H36*J36)/(E36*F36-10000)) -> 373.4369 | M36: =H36*J36 -> 13.830996 | N36: =IF(G36="F",(F36*J36)/(100+F36),IF(G36="U",IF(E36<0,(-E36*J36)/(100-E36),IF(E36>0,(100*J36)/(E36+100),0)),0)) -> 559.28159 | O36: =IF(AND(G36="F",E36<>""),(100*J36)/(100+F36),IF(G36="U",IF(E36<0,(100*J36)/(100-E36),IF(E36>0,(E36*J36)/(E36+100),0)),0)) -> 367.94841 | P36: =I36*J36 -> 23.157592 | Q36: F | R36: F | S36: =IF((Q36="F"),IF(R36=G36,P36,0),IF(Q36="E",M36,0)) -> 23.157592 | W36: WEEK 6 | X36: 45270 | Y36: {=SUM(_xlfn._xlws.FILTER(S:S,A:A=X36,0))} -> 101.54202
A37: 45260 | B37: Sports Interaction | C37: Fanduel | D37: Khris Middleton Assists (O/U 3.5) | E37: -105 | F37: 108 | G37: F | H37: =IF(E37<0,100*(E37+F37)/(10000-200*E37-E37*F37),IF(E37>0,(E37*F37-10000)/(100*(E37+F37+200)),0)) -> 0.0070854983 | I37: =IF(E37<0,IF(G37="F",-100*(E37+F37)/(E37*(F37+100)),IF(G37="U",-(F37+E37)/(E37-100),0)),IF(E37>0,IF(G37="F",(E37*F37-10000)/(100*F37+10000),IF(G37="U",(E37*F37-10000)/(100*E37+10000),0)),0)) -> 0.013736264 | J37: 577.78 | K37: =IF(E37<0,(H37*J37*-E37*(1+F37/100))/(E37+F37),(100*H37*J37*(100+F37))/(E37*F37-10000)) -> 298.03295 | L37: =IF(E37<0,((100-E37)*H37*J37)/(E37+F37),100*((100+E37)*H37*J37)/(E37*F37-10000)) -> 279.74705 | M37: =H37*J37 -> 4.0938592 | N37: =IF(G37="F",(F37*J37)/(100+F37),IF(G37="U",IF(E37<0,(-E37*J37)/(100-E37),IF(E37>0,(100*J37)/(E37+100),0)),0)) -> 300.00115 | O37: =IF(AND(G37="F",E37<>""),(100*J37)/(100+F37),IF(G37="U",IF(E37<0,(100*J37)/(100-E37),IF(E37>0,(E37*J37)/(E37+100),0)),0)) -> 277.77885 | P37: =I37*J37 -> 7.9365385 | Q37: F | R37: U | S37: =IF((Q37="F"),IF(R37=G37,P37,0),IF(Q37="E",M37,0)) -> 0 | W37: =SUM(Y36:Y42) -> 101.54202 | X37: 45271 | Y37: {=SUM(_xlfn._xlws.FILTER(S:S,A:A=X37,0))} -> 0
A38: 45260 | B38: NorthStar | C38: DraftKings | D38: Ryan Nugent-Hopkins PowerPlay Points (U/O 0.5) | E38: -200 | F38: 210 | G38: F | H38: =IF(E38<0,100*(E38+F38)/(10000-200*E38-E38*F38),IF(E38>0,(E38*F38-10000)/(100*(E38+F38+200)),0)) -> 0.010869565 | I38: =IF(E38<0,IF(G38="F",-100*(E38+F38)/(E38*(F38+100)),IF(G38="U",-(F38+E38)/(E38-100),0)),IF(E38>0,IF(G38="F",(E38*F38-10000)/(100*F38+10000),IF(G38="U",(E38*F38-10000)/(100*E38+10000),0)),0)) -> 0.016129032 | J38: 956.01 | K38: =IF(E38<0,(H38*J38*-E38*(1+F38/100))/(E38+F38),(100*H38*J38*(100+F38))/(E38*F38-10000)) -> 644.26761 | L38: =IF(E38<0,((100-E38)*H38*J38)/(E38+F38),100*((100+E38)*H38*J38)/(E38*F38-10000)) -> 311.74239 | M38: =H38*J38 -> 10.391413 | N38: =IF(G38="F",(F38*J38)/(100+F38),IF(G38="U",IF(E38<0,(-E38*J38)/(100-E38),IF(E38>0,(100*J38)/(E38+100),0)),0)) -> 647.61968 | O38: =IF(AND(G38="F",E38<>""),(100*J38)/(100+F38),IF(G38="U",IF(E38<0,(100*J38)/(100-E38),IF(E38>0,(E38*J38)/(E38+100),0)),0)) -> 308.39032 | P38: =I38*J38 -> 15.419516 | Q38: F | R38: F | S38: =IF((Q38="F"),IF(R38=G38,P38,0),IF(Q38="E",M38,0)) -> 15.419516 | X38: 45272 | Y38: {=SUM(_xlfn._xlws.FILTER(S:S,A:A=X38,0))} -> 0
A39: 45262 | B39: DraftKings | C39: BetRivers | D39: Ashton Jeanty Receiving Yards (O/U 29.5) | E39: -115 | F39: 120 | G39: F | H39: =IF(E39<0,100*(E39+F39)/(10000-200*E39-E39*F39),IF(E39>0,(E39*F39-10000)/(100*(E39+F39+200)),0)) -> 0.010683761 | I39: =IF(E39<0,IF(G39="F",-100*(E39+F39)/(E39*(F39+100)),IF(G39="U",-(F39+E39)/(E39-100),0)),IF(E39>0,IF(G39="F",(E39*F39-10000)/(100*F39+10000),IF(G39="U",(E39*F39-10000)/(100*E39+10000),0)),0)) -> 0.019762846 | J39: 660 | K39: =IF(E39<0,(H39*J39*-E39*(1+F39/100))/(E39+F39),(100*H39*J39*(100+F39))/(E39*F39-10000)) -> 356.79487 | L39: =IF(E39<0,((100-E39)*H39*J39)/(E39+F39),100*((100+E39)*H39*J39)/(E39*F39-10000)) -> 303.20513 | M39: =H39*J39 -> 7.0512821 | N39: =IF(G39="F",(F39*J39)/(100+F39),IF(G39="U",IF(E39<0,(-E39*J39)/(100-E39),IF(E39>0,(100*J39)/(E39+100),0)),0)) -> 360 | O39: =IF(AND(G39="F",E39<>""),(100*J39)/(100+F39),IF(G39="U",IF(E39<0,(100*J39)/(100-E39),IF(E39>0,(E39*J39)/(E39+100),0)),0)) -> 300 | P39: =I39*J39 -> 13.043478 | Q39: F | R39: U | S39: =IF((Q39="F"),IF(R39=G39,P39,0),IF(Q39="E",M39,0)) -> 0 | X39: 45273 | Y39: {=SUM(_xlfn._xlws.FILTER(S:S,A:A=X39,0))} -> 0
A40: 45262 | B40: Bet365 | C40: BetMGM | D40: Toledo v George Mason Moneyline | E40: -145 | F40: 155 | G40: F | H40: =IF(E40<0,100*(E40+F40)/(10000-200*E40-E40*F40),IF(E40>0,(E40*F40-10000)/(100*(E40+F40+200)),0)) -> 0.016266775 | I40: =IF(E40<0,IF(G40="F",-100*(E40+F40)/(E40*(F40+100)),IF(G40="U",-(F40+E40)/(E40-100),0)),IF(E40>0,IF(G40="F",(E40*F40-10000)/(100*F40+10000),IF(G40="U",(E40*F40-10000)/(100*E40+10000),0)),0)) -> 0.027045301 | J40: 1287.51 | K40: =IF(E40<0,(H40*J40*-E40*(1+F40/100))/(E40+F40),(100*H40*J40*(100+F40))/(E40*F40-10000)) -> 774.39093 | L40: =IF(E40<0,((100-E40)*H40*J40)/(E40+F40),100*((100+E40)*H40*J40)/(E40*F40-10000)) -> 513.11907 | M40: =H40*J40 -> 20.943636 | N40: =IF(G40="F",(F40*J40)/(100+F40),IF(G40="U",IF(E40<0,(-E40*J40)/(100-E40),IF(E40>0,(100*J40)/(E40+100),0)),0)) -> 782.60412 | O40: =IF(AND(G40="F",E40<>""),(100*J40)/(100+F40),IF(G40="U",IF(E40<0,(100*J40)/(100-E40),IF(E40>0,(E40*J40)/(E40+100),0)),0)) -> 504.90588 | P40: =I40*J40 -> 34.821095 | Q40: F | R40: U | S40: =IF((Q40="F"),IF(R40=G40,P40,0),IF(Q40="E",M40,0)) -> 0 | X40: 45274 | Y40: {=SUM(_xlfn._xlws.FILTER(S:S,A:A=X40,0))} -> 0
...

Sheet +EV Betting
A1: Date | B1: Prop | C1: Sportsbook | D1: PinnaclePickLine | E1: PinnacleOppLine | F1: WagerLine | G1: TrueOdds | H1: KellyWager | I1: ActualWager | J1: Payout | K1: EV ($) | L1: EV (%) | M1: Event(Y/N) | N1: Profit/Loss | O1: BANKROLL ($) | P1: TOTAL WAGERED | S1: DATE | T1: Daily P/L | U1: Overall P/L | V1: Wagered | W1: # Wagers | X1: EV ($) | Y1: Overall EV ($) | Z1: AVG | AD1: Unique Pinny TrueOdds | AE1: # Occurences | AF1: Hit Rate | AG1: Difference from True Odds to Real Life Results | AH1: Average of Difference (Pinny Accuracy) | AO1: Pinny Equiv Payout | AP1: Pinny Equiv P/L | AQ1: Reg P/L | AR1: Cumulative Difference | AS1: Total Pinny Equiv P/L | AW1: April | AX1: May
A2: 45255 | B2: North Texas Moneyline (v UAB) | C2: TheScore | D2: -131 | E2: 130 | F2: -130 | G2: =IF(AND(D2<0,E2<0),(D2*E2-100*D2)/(2*D2*E2-100*D2-100*E2),IF(OR(AND(D2<0,E2>0),AND(D2>0,E2<0)),IF(D2<=E2,(100*D2+D2*E2)/(200*D2+D2*E2-10000),(100*E2-10000)/(200*E2+D2*E2-10000)),0)) -> 0.56603419 | H2: =IF(F2<0,G2+(1-G2)*(F2/100),IF(F2>0,G2-(1-G2)*(100/F2),0))*$O$2/2 -> 4.6965997 | I2: 200 | J2: =IF(F2<0,I2/(F2/-100),I2*F2/100) -> 153.84615 | K2: =G2*J2-(1-G2)*I2 -> 0.28902152 | L2: =IF(F2>0,(G2*F2/100-(1-G2)),IF(F2<0,(G2*100/-F2-(1-G2)),0)) -> 0.0014451076 | M2: Y | N2: =IF(ISERROR(SEARCH("(Bonus Bet)",B2)),IF(M2="Y",J2,IF(M2="N",-I2,0)),IF(M2="N",0,IF(M2="Y",J2,0))) -> 153.84615 | O2: 5000 | P2: =SUM(I:I) -> 381866.31 | R2: WEEK 1 | S2: 45254 | T2: {=SUM(_xlfn._xlws.FILTER(N:N,A:A=S2,0))} -> 83.333333 | U2: =T2 -> 83.333333 | V2: {=SUM(_xlfn._xlws.FILTER(I:I,A:A=S2,0))} -> 200 | W2: {=COUNT(_xlfn._xlws.FILTER(I:I,A:A=S2,""))} -> 1 | X2: {=SUM(_xlfn._xlws.FILTER(K:K,A:A=S2,0))} -> 0 | Y2: =0 -> 0 | Z2: =AVERAGEIF(W:W,"<>0") -> 25.16129 | AA2: Bets/Day | AD2: {=_xlfn.UNIQUE(G2:G4000,FALSE,FALSE)} -> 0.56603419 | AE2: {=COUNTIF(G2:G4000,AD2:AD2001)} -> 2 | AF2: =COUNTIFS($G$2:$G$4000,AD2,$M$2:$M$4000,"=Y")/AE2 -> 1 | AG2: =AD2-AF2 -> -0.43396581 | AH2: =AVERAGEIF(AG:AG,"<>0") -> 0.0086328667 | AK2: {=_xlfn._xlws.FILTER(AD2:AD2000,(AD2:AD2000<0.1)*(AD2:AD2000>0))} -> 0.090334237 | AL2: {=COUNTIF(G2:G4000,AK2:AK48)} -> 1 | AM2: =COUNTIFS($G$2:$G$4000,AK2,$M$2:$M$4000,"=Y") -> 0 | AO2: =IF(D2<0,I2/(D2/-100),I2*D2/100) -> 152.67176 | AP2: =IF(ISERROR(SEARCH("(Bonus Bet)",B2)),IF(M2="Y",AO2,IF(M2="N",-I2,0)),IF(M2="N",0,IF(M2="Y",AO2,0))) -> 152.67176 | AQ2: =N2 -> 153.84615 | AR2: =AQ2-AP2 -> 1.1743981 | AS2: =SUM(AP:AP) -> -25279.526 | AV2: In | AW2: -4020.9 | AX2: -2034.78
A3: 45257 | B3: Alexander Mattison Under 2.5 Receptions | C3: Fanduel | D3: -154 | E3: 154 | F3: -154 | G3: =IF(AND(D3<0,E3<0),(D3*E3-100*D3)/(2*D3*E3-100*D3-100*E3),IF(OR(AND(D3<0,E3>0),AND(D3>0,E3<0)),IF(D3<=E3,(100*D3+D3*E3)/(200*D3+D3*E3-10000),(100*E3-10000)/(200*E3+D3*E3-10000)),0)) -> 0.60629921 | H3: =IF(F3<0,G3+(1-G3)*(F3/100),IF(F3>0,G3-(1-G3)*(100/F3),0))*$O$2/2 -> 2.7755576e-13 | I3: 200 | J3: =IF(F3<0,I3/(F3/-100),I3*F3/100) -> 129.87013 | K3: =G3*J3-(1-G3)*I3 -> 0 | L3: =IF(F3>0,(G3*F3/100-(1-G3)),IF(F3<0,(G3*100/-F3-(1-G3)),0)) -> 5.5511151e-17 | M3: Y | N3: =IF(ISERROR(SEARCH("(Bonus Bet)",B3)),IF(M3="Y",J3,IF(M3="N",-I3,0)),IF(M3="N",0,IF(M3="Y",J3,0))) -> 129.87013 | O3: OVERALL EV ($) | P3: AVERAGE EV (%) | R3: =SUM(T2:T10) -> 1240.7935 | S3: 45255 | T3: {=SUM(_xlfn._xlws.FILTER(N:N,A:A=S3,0))} -> 153.84615 | U3: =U2+T3 -> 237.17949 | V3: {=SUM(_xlfn._xlws.FILTER(I:I,A:A=S3,0))} -> 200 | W3: {=COUNT(_xlfn._xlws.FILTER(I:I,A:A=S3,""))} -> 1 | X3: {=SUM(_xlfn._xlws.FILTER(K:K,A:A=S3,0))} -> 0.28902152 | Y3: =Y2+X3 -> 0.28902152 | Z3: =AVERAGEIF(V:V,"<>0") -> 2463.6536 | AA3: Wagered/Day | AD3: 0.60629921 | AE3: 2 | AF3: =COUNTIFS($G$2:$G$4000,AD3,$M$2:$M$4000,"=Y")/AE3 -> 1 | AG3: =AD3-AF3 -> -0.39370079 | AK3: 0.097786724 | AL3: 1 | AM3: =COUNTIFS($G$2:$G$4000,AK3,$M$2:$M$4000,"=Y") -> 0 | AO3: =IF(D3<0,I3/(D3/-100),I3*D3/100) -> 129.87013 | AP3: =IF(ISERROR(SEARCH("(Bonus Bet)",B3)),IF(M3="Y",AO3,IF(M3="N",-I3,0)),IF(M3="N",0,IF(M3="Y",AO3,0))) -> 129.87013 | AQ3: =N3 -> 129.87013 | AR3: =AQ3-AP3+AR2 -> 1.1743981 | AV3: Out | AW3: 3767.28 | AX3: 1569.73
A4: 45256 | B4: Seth Jarvis Under 2.5 Shots on Goal | C4: DraftKings | D4: -110 | E4: 110 | F4: -110 | G4: =IF(AND(D4<0,E4<0),(D4*E4-100*D4)/(2*D4*E4-100*D4-100*E4),IF(OR(AND(D4<0,E4>0),AND(D4>0,E4<0)),IF(D4<=E4,(100*D4+D4*E4)/(200*D4+D4*E4-10000),(100*E4-10000)/(200*E4+D4*E4-10000)),0)) -> 0.52380952 | H4: =IF(F4<0,G4+(1-G4)*(F4/100),IF(F4>0,G4-(1-G4)*(100/F4),0))*$O$2/2 -> 0 | I4: 200 | J4: =IF(F4<0,I4/(F4/-100),I4*F4/100) -> 181.81818 | K4: =G4*J4-(1-G4)*I4 -> 0 | L4: =IF(F4>0,(G4*F4/100-(1-G4)),IF(F4<0,(G4*100/-F4-(1-G4)),0)) -> 5.5511151e-17 | M4: Y | N4: =IF(ISERROR(SEARCH("(Bonus Bet)",B4)),IF(M4="Y",J4,IF(M4="N",-I4,0)),IF(M4="N",0,IF(M4="Y",J4,0))) -> 181.81818 | O4: =SUM(K:K) -> 22401.594 | P4: =AVERAGEIF(L:L,"<>0") -> 0.058637668 | S4: 45256 | T4: {=SUM(_xlfn._xlws.FILTER(N:N,A:A=S4,0))} -> 335.66434 | U4: =U3+T4 -> 572.84382 | V4: {=SUM(_xlfn._xlws.FILTER(I:I,A:A=S4,0))} -> 400 | W4: {=COUNT(_xlfn._xlws.FILTER(I:I,A:A=S4,""))} -> 2 | X4: {=SUM(_xlfn._xlws.FILTER(K:K,A:A=S4,0))} -> 0.28902152 | Y4: =Y3+X4 -> 0.57804304 | Z4: =Z3/Z2 -> 97.914438 | AA4: per Wager | AD4: 0.52380952 | AE4: 1 | AF4: =COUNTIFS($G$2:$G$4000,AD4,$M$2:$M$4000,"=Y")/AE4 -> 1 | AG4: =AD4-AF4 -> -0.47619048 | AK4: 0.097128243 | AL4: 1 | AM4: =COUNTIFS($G$2:$G$4000,AK4,$M$2:$M$4000,"=Y") -> 0 | AO4: =IF(D4<0,I4/(D4/-100),I4*D4/100) -> 181.81818 | AP4: =IF(ISERROR(SEARCH("(Bonus Bet)",B4)),IF(M4="Y",AO4,IF(M4="N",-I4,0)),IF(M4="N",0,IF(M4="Y",AO4,0))) -> 181.81818 | AQ4: =N4 -> 181.81818 | AR4: =AQ4-AP4+AR3 -> 1.1743981
A5: 45256 | B5: Zay Flowers Over 4.5 Total Receptions | C5: Fanduel | D5: -131 | E5: 130 | F5: -130 | G5: =IF(AND(D5<0,E5<0),(D5*E5-100*D5)/(2*D5*E5-100*D5-100*E5),IF(OR(AND(D5<0,E5>0),AND(D5>0,E5<0)),IF(D5<=E5,(100*D5+D5*E5)/(200*D5+D5*E5-10000),(100*E5-10000)/(200*E5+D5*E5-10000)),0)) -> 0.56603419 | H5: =IF(F5<0,G5+(1-G5)*(F5/100),IF(F5>0,G5-(1-G5)*(100/F5),0))*$O$2/2 -> 4.6965997 | I5: 200 | J5: =IF(F5<0,I5/(F5/-100),I5*F5/100) -> 153.84615 | K5: =G5*J5-(1-G5)*I5 -> 0.28902152 | L5: =IF(F5>0,(G5*F5/100-(1-G5)),IF(F5<0,(G5*100/-F5-(1-G5)),0)) -> 0.0014451076 | M5: Y | N5: =IF(ISERROR(SEARCH("(Bonus Bet)",B5)),IF(M5="Y",J5,IF(M5="N",-I5,0)),IF(M5="N",0,IF(M5="Y",J5,0))) -> 153.84615 | P5: TOTAL PROFIT/LOSS | S5: 45257 | T5: {=SUM(_xlfn._xlws.FILTER(N:N,A:A=S5,0))} -> 103.78317 | U5: =U4+T5 -> 676.627 | V5: {=SUM(_xlfn._xlws.FILTER(I:I,A:A=S5,0))} -> 600 | W5: {=COUNT(_xlfn._xlws.FILTER(I:I,A:A=S5,""))} -> 3 | X5: {=SUM(_xlfn._xlws.FILTER(K:K,A:A=S5,0))} -> 3.0405981 | Y5: =Y4+X5 -> 3.6186412 | AD5: 0.70588235 | AE5: 1 | AF5: =COUNTIFS($G$2:$G$4000,AD5,$M$2:$M$4000,"=Y")/AE5 -> 1 | AG5: =AD5-AF5 -> -0.29411765 | AK5: 0.054003766 | AL5: 1 | AM5: =COUNTIFS($G$2:$G$4000,AK5,$M$2:$M$4000,"=Y") -> 0 | AO5: =IF(D5<0,I5/(D5/-100),I5*D5/100) -> 152.67176 | AP5: =IF(ISERROR(SEARCH("(Bonus Bet)",B5)),IF(M5="Y",AO5,IF(M5="N",-I5,0)),IF(M5="N",0,IF(M5="Y",AO5,0))) -> 152.67176 | AQ5: =N5 -> 153.84615 | AR5: =AQ5-AP5+AR4 -> 2.3487962
A6: 45254 | B6: Eurospin Pinerolo Moneyline (v Bergamo) | C6: Unibet | D6: -240 | E6: 240 | F6: -240 | G6: =IF(AND(D6<0,E6<0),(D6*E6-100*D6)/(2*D6*E6-100*D6-100*E6),IF(OR(AND(D6<0,E6>0),AND(D6>0,E6<0)),IF(D6<=E6,(100*D6+D6*E6)/(200*D6+D6*E6-10000),(100*E6-10000)/(200*E6+D6*E6-10000)),0)) -> 0.70588235 | H6: =IF(F6<0,G6+(1-G6)*(F6/100),IF(F6>0,G6-(1-G6)*(100/F6),0))*$O$2/2 -> 5.5511151e-13 | I6: 200 | J6: =IF(F6<0,I6/(F6/-100),I6*F6/100) -> 83.333333 | K6: =G6*J6-(1-G6)*I6 -> 0 | L6: =IF(F6>0,(G6*F6/100-(1-G6)),IF(F6<0,(G6*100/-F6-(1-G6)),0)) -> 5.5511151e-17 | M6: Y | N6: =IF(ISERROR(SEARCH("(Bonus Bet)",B6)),IF(M6="Y",J6,IF(M6="N",-I6,0)),IF(M6="N",0,IF(M6="Y",J6,0))) -> 83.333333 | P6: =SUM(N:N) -> 16259.954 | S6: 45258 | T6: {=SUM(_xlfn._xlws.FILTER(N:N,A:A=S6,0))} -> 160.62378 | U6: =U5+T6 -> 837.25078 | V6: {=SUM(_xlfn._xlws.FILTER(I:I,A:A=S6,0))} -> 600 | W6: {=COUNT(_xlfn._xlws.FILTER(I:I,A:A=S6,""))} -> 4 | X6: {=SUM(_xlfn._xlws.FILTER(K:K,A:A=S6,0))} -> 53.472588 | Y6: =Y5+X6 -> 57.091229 | AD6: 0.56195695 | AE6: 1 | AF6: =COUNTIFS($G$2:$G$4000,AD6,$M$2:$M$4000,"=Y")/AE6 -> 0 | AG6: =AD6-AF6 -> 0.56195695 | AK6: 0.095510984 | AL6: 1 | AM6: =COUNTIFS($G$2:$G$4000,AK6,$M$2:$M$4000,"=Y") -> 0 | AO6: =IF(D6<0,I6/(D6/-100),I6*D6/100) -> 83.333333 | AP6: =IF(ISERROR(SEARCH("(Bonus Bet)",B6)),IF(M6="Y",AO6,IF(M6="N",-I6,0)),IF(M6="N",0,IF(M6="Y",AO6,0))) -> 83.333333 | AQ6: =N6 -> 83.333333 | AR6: =AQ6-AP6+AR5 -> 2.3487962
A7: 45262 | B7: Jamey-Lyn Horth Moneyline (v Hardy) | C7: NorthStar | D7: -143 | E7: 118 | F7: -107 | G7: =IF(AND(D7<0,E7<0),(D7*E7-100*D7)/(2*D7*E7-100*D7-100*E7),IF(OR(AND(D7<0,E7>0),AND(D7>0,E7<0)),IF(D7<=E7,(100*D7+D7*E7)/(200*D7+D7*E7-10000),(100*E7-10000)/(200*E7+D7*E7-10000)),0)) -> 0.56195695 | H7: =IF(F7<0,G7+(1-G7)*(F7/100),IF(F7>0,G7-(1-G7)*(100/F7),0))*$O$2/2 -> 233.12723 | I7: 150 | J7: =IF(F7<0,I7/(F7/-100),I7*F7/100) -> 140.18692 | K7: =G7*J7-(1-G7)*I7 -> 13.072555 | L7: =IF(F7>0,(G7*F7/100-(1-G7)),IF(F7<0,(G7*100/-F7-(1-G7)),0)) -> 0.087150367 | M7: N | N7: =IF(ISERROR(SEARCH("(Bonus Bet)",B7)),IF(M7="Y",J7,IF(M7="N",-I7,0)),IF(M7="N",0,IF(M7="Y",J7,0))) -> -150 | P7: PROFIT MARGIN | S7: 45259 | T7: {=SUM(_xlfn._xlws.FILTER(N:N,A:A=S7,0))} -> -173.80171 | U7: =U6+T7 -> 663.44907 | V7: {=SUM(_xlfn._xlws.FILTER(I:I,A:A=S7,0))} -> 1753.83 | W7: {=COUNT(_xlfn._xlws.FILTER(I:I,A:A=S7,""))} -> 8 | X7: {=SUM(_xlfn._xlws.FILTER(K:K,A:A=S7,0))} -> 66.161087 | Y7: =Y6+X7 -> 123.25232 | AD7: 0.56608812 | AE7: 1 | AF7: =COUNTIFS($G$2:$G$4000,AD7,$M$2:$M$4000,"=Y")/AE7 -> 1 | AG7: =AD7-AF7 -> -0.43391188 | AK7: 0.069005262 | AL7: 1 | AM7: =COUNTIFS($G$2:$G$4000,AK7,$M$2:$M$4000,"=Y") -> 0 | AO7: =IF(D7<0,I7/(D7/-100),I7*D7/100) -> 104.8951 | AP7: =IF(ISERROR(SEARCH("(Bonus Bet)",B7)),IF(M7="Y",AO7,IF(M7="N",-I7,0)),IF(M7="N",0,IF(M7="Y",AO7,0))) -> -150 | AQ7: =N7 -> -150 | AR7: =AQ7-AP7+AR6 -> 2.3487962
A8: 45262 | B8: Drakkar Klose Moneyline (v Solecki) | C8: DraftKings | D8: -160 | E8: 112 | F8: -130 | G8: =IF(AND(D8<0,E8<0),(D8*E8-100*D8)/(2*D8*E8-100*D8-100*E8),IF(OR(AND(D8<0,E8>0),AND(D8>0,E8<0)),IF(D8<=E8,(100*D8+D8*E8)/(200*D8+D8*E8-10000),(100*E8-10000)/(200*E8+D8*E8-10000)),0)) -> 0.56608812 | H8: =IF(F8<0,G8+(1-G8)*(F8/100),IF(F8>0,G8-(1-G8)*(100/F8),0))*$O$2/2 -> 5.0066756 | I8: 200 | J8: =IF(F8<0,I8/(F8/-100),I8*F8/100) -> 153.84615 | K8: =G8*J8-(1-G8)*I8 -> 0.30810311 | L8: =IF(F8>0,(G8*F8/100-(1-G8)),IF(F8<0,(G8*100/-F8-(1-G8)),0)) -> 0.0015405156 | M8: Y | N8: =IF(ISERROR(SEARCH("(Bonus Bet)",B8)),IF(M8="Y",J8,IF(M8="N",-I8,0)),IF(M8="N",0,IF(M8="Y",J8,0))) -> 153.84615 | P8: =P6/P2 -> 0.042580226 | S8: 45260 | T8: {=SUM(_xlfn._xlws.FILTER(N:N,A:A=S8,0))} -> 509.40873 | U8: =U7+T8 -> 1172.8578 | V8: {=SUM(_xlfn._xlws.FILTER(I:I,A:A=S8,0))} -> 1000 | W8: {=COUNT(_xlfn._xlws.FILTER(I:I,A:A=S8,""))} -> 5 | X8: {=SUM(_xlfn._xlws.FILTER(K:K,A:A=S8,0))} -> 67.413947 | Y8: =Y7+X8 -> 190.66626 | AD8: 0.58827199 | AE8: 1 | AF8: =COUNTIFS($G$2:$G$4000,AD8,$M$2:$M$4000,"=Y")/AE8 -> 0 | AG8: =AD8-AF8 -> 0.58827199 | AK8: 0.0751976 | AL8: 1 | AM8: =COUNTIFS($G$2:$G$4000,AK8,$M$2:$M$4000,"=Y") -> 0 | AO8: =IF(D8<0,I8/(D8/-100),I8*D8/100) -> 125 | AP8: =IF(ISERROR(SEARCH("(Bonus Bet)",B8)),IF(M8="Y",AO8,IF(M8="N",-I8,0)),IF(M8="N",0,IF(M8="Y",AO8,0))) -> 125 | AQ8: =N8 -> 153.84615 | AR8: =AQ8-AP8+AR7 -> 31.19495
A9: 45262 | B9: Rob Font Moneyline (v Figueiredo) | C9: DraftKings | D9: -164 | E9: 130 | F9: -135 | G9: =IF(AND(D9<0,E9<0),(D9*E9-100*D9)/(2*D9*E9-100*D9-100*E9),IF(OR(AND(D9<0,E9>0),AND(D9>0,E9<0)),IF(D9<=E9,(100*D9+D9*E9)/(200*D9+D9*E9-10000),(100*E9-10000)/(200*E9+D9*E9-10000)),0)) -> 0.58827199 | H9: =IF(F9<0,G9+(1-G9)*(F9/100),IF(F9>0,G9-(1-G9)*(100/F9),0))*$O$2/2 -> 81.097941 | I9: 200 | J9: =IF(F9<0,I9/(F9/-100),I9*F9/100) -> 148.14815 | K9: =G9*J9-(1-G9)*I9 -> 4.8058039 | L9: =IF(F9>0,(G9*F9/100-(1-G9)),IF(F9<0,(G9*100/-F9-(1-G9)),0)) -> 0.02402902 | M9: N | N9: =IF(ISERROR(SEARCH("(Bonus Bet)",B9)),IF(M9="Y",J9,IF(M9="N",-I9,0)),IF(M9="N",0,IF(M9="Y",J9,0))) -> -200 | S9: 45261 | T9: {=SUM(_xlfn._xlws.FILTER(N:N,A:A=S9,0))} -> 293.22651 | U9: =U8+T9 -> 1466.0843 | V9: {=SUM(_xlfn._xlws.FILTER(I:I,A:A=S9,0))} -> 608.33 | W9: {=COUNT(_xlfn._xlws.FILTER(I:I,A:A=S9,""))} -> 2 | X9: {=SUM(_xlfn._xlws.FILTER(K:K,A:A=S9,0))} -> 30.955526 | Y9: =Y8+X9 -> 221.62179 | AD9: 0.56560284 | AE9: 1 | AF9: =COUNTIFS($G$2:$G$4000,AD9,$M$2:$M$4000,"=Y")/AE9 -> 1 | AG9: =AD9-AF9 -> -0.43439716 | AK9: 0.094463783 | AL9: 1 | AM9: =COUNTIFS($G$2:$G$4000,AK9,$M$2:$M$4000,"=Y") -> 0 | AO9: =IF(D9<0,I9/(D9/-100),I9*D9/100) -> 121.95122 | AP9: =IF(ISERROR(SEARCH("(Bonus Bet)",B9)),IF(M9="Y",AO9,IF(M9="N",-I9,0)),IF(M9="N",0,IF(M9="Y",AO9,0))) -> -200 | AQ9: =N9 -> -200 | AR9: =AQ9-AP9+AR8 -> 31.19495
